Process A (arrival time 9 ms) 16 CPU bursts (tau 100ms)
Process B (arrival time 18 ms) 21 CPU bursts (tau 100ms)
Process C (arrival time 42 ms) 4 CPU bursts (tau 100ms)
Process D (arrival time 156 ms) 11 CPU bursts (tau 100ms)
Process E (arrival time 134 ms) 55 CPU bursts (tau 100ms)
Process F (arrival time 106 ms) 34 CPU bursts (tau 100ms)
Process G (arrival time 65 ms) 80 CPU bursts (tau 100ms)
Process H (arrival time 11 ms) 83 CPU bursts (tau 100ms)
Process I (arrival time 68 ms) 77 CPU bursts (tau 100ms)
Process J (arrival time 0 ms) 10 CPU bursts (tau 100ms)
Process K (arrival time 7 ms) 13 CPU bursts (tau 100ms)
Process L (arrival time 189 ms) 7 CPU bursts (tau 100ms)
Process M (arrival time 16 ms) 48 CPU bursts (tau 100ms)
Process N (arrival time 122 ms) 31 CPU bursts (tau 100ms)
Process O (arrival time 29 ms) 31 CPU bursts (tau 100ms)
Process P (arrival time 159 ms) 16 CPU bursts (tau 100ms)

time 0ms: Simulator started for FCFS [Q empty]
time 0ms: Process J arrived; added to ready queue [Q J]
time 2ms: Process J started using the CPU for 40ms burst [Q empty]
time 7ms: Process K arrived; added to ready queue [Q K]
time 9ms: Process A arrived; added to ready queue [Q AK]
time 11ms: Process H arrived; added to ready queue [Q AHK]
time 16ms: Process M arrived; added to ready queue [Q AHKM]
time 18ms: Process B arrived; added to ready queue [Q ABHKM]
time 29ms: Process O arrived; added to ready queue [Q ABHKMO]
time 42ms: Process J completed a CPU burst; 9 bursts to go [Q ABHKMO]
time 42ms: Process J switching out of CPU; will block on I/O until time 74ms [Q ABHKMO]
time 42ms: Process C arrived; added to ready queue [Q ABCHKMO]
time 46ms: Process K started using the CPU for 64ms burst [Q ABCHMO]
time 65ms: Process G arrived; added to ready queue [Q ABCGHMO]
time 68ms: Process I arrived; added to ready queue [Q ABCGHIMO]
time 74ms: Process J completed I/O; added to ready queue [Q ABCGHIJMO]
time 106ms: Process F arrived; added to ready queue [Q ABCFGHIJMO]
time 110ms: Process K completed a CPU burst; 12 bursts to go [Q ABCFGHIJMO]
time 110ms: Process K switching out of CPU; will block on I/O until time 1072ms [Q ABCFGHIJMO]
time 114ms: Process A started using the CPU for 56ms burst [Q BCFGHIJMO]
time 122ms: Process N arrived; added to ready queue [Q BCFGHIJMNO]
time 134ms: Process E arrived; added to ready queue [Q BCEFGHIJMNO]
time 156ms: Process D arrived; added to ready queue [Q BCDEFGHIJMNO]
time 159ms: Process P arrived; added to ready queue [Q BCDEFGHIJMNOP]
time 170ms: Process A completed a CPU burst; 15 bursts to go [Q BCDEFGHIJMNOP]
time 170ms: Process A switching out of CPU; will block on I/O until time 402ms [Q BCDEFGHIJMNOP]
time 174ms: Process H started using the CPU for 96ms burst [Q BCDEFGIJMNOP]
time 189ms: Process L arrived; added to ready queue [Q BCDEFGIJLMNOP]
time 270ms: Process H completed a CPU burst; 82 bursts to go [Q BCDEFGIJLMNOP]
time 270ms: Process H switching out of CPU; will block on I/O until time 942ms [Q BCDEFGIJLMNOP]
time 274ms: Process M started using the CPU for 22ms burst [Q BCDEFGIJLNOP]
time 296ms: Process M completed a CPU burst; 47 bursts to go [Q BCDEFGIJLNOP]
time 296ms: Process M switching out of CPU; will block on I/O until time 468ms [Q BCDEFGIJLNOP]
time 300ms: Process B started using the CPU for 106ms burst [Q CDEFGIJLNOP]
time 402ms: Process A completed I/O; added to ready queue [Q ACDEFGIJLNOP]
time 406ms: Process B completed a CPU burst; 20 bursts to go [Q ACDEFGIJLNOP]
time 406ms: Process B switching out of CPU; will block on I/O until time 1968ms [Q ACDEFGIJLNOP]
time 410ms: Process O started using the CPU for 156ms burst [Q ACDEFGIJLNP]
time 468ms: Process M completed I/O; added to ready queue [Q ACDEFGIJLMNP]
time 566ms: Process O completed a CPU burst; 30 bursts to go [Q ACDEFGIJLMNP]
time 566ms: Process O switching out of CPU; will block on I/O until time 1238ms [Q ACDEFGIJLMNP]
time 570ms: Process C started using the CPU for 94ms burst [Q ADEFGIJLMNP]
time 664ms: Process C completed a CPU burst; 3 bursts to go [Q ADEFGIJLMNP]
time 664ms: Process C switching out of CPU; will block on I/O until time 2246ms [Q ADEFGIJLMNP]
time 668ms: Process G started using the CPU for 70ms burst [Q ADEFIJLMNP]
time 738ms: Process G completed a CPU burst; 79 bursts to go [Q ADEFIJLMNP]
time 738ms: Process G switching out of CPU; will block on I/O until time 1050ms [Q ADEFIJLMNP]
time 742ms: Process I started using the CPU for 220ms burst [Q ADEFJLMNP]
time 942ms: Process H completed I/O; added to ready queue [Q ADEFHJLMNP]
time 962ms: Process I completed a CPU burst; 76 bursts to go [Q ADEFHJLMNP]
time 962ms: Process I switching out of CPU; will block on I/O until time 1154ms [Q ADEFHJLMNP]
time 966ms: Process J started using the CPU for 204ms burst [Q ADEFHLMNP]
time 4247ms: Process C terminated [Q BEHIJKN]
time 8522ms: Process L terminated [Q BDEFGIJNP]
time 9024ms: Process J terminated [Q DHKNO]
time 14007ms: Process D terminated [Q I]
time 14548ms: Process K terminated [Q empty]
time 16464ms: Process A terminated [Q BGHIMN]
time 22473ms: Process B terminated [Q FHO]
time 25149ms: Process P terminated [Q EGHMN]
time 32371ms: Process F terminated [Q H]
time 35911ms: Process N terminated [Q H]
time 36171ms: Process O terminated [Q E]
time 50419ms: Process E terminated [Q empty]
time 53366ms: Process M terminated [Q empty]
time 72201ms: Process H terminated [Q empty]
time 75337ms: Process I terminated [Q empty]
time 78350ms: Process G terminated [Q empty]
time 78352ms: Simulator ended for FCFS [Q empty]

time 0ms: Simulator started for SJF [Q empty]
time 0ms: Process J (tau 100ms) arrived; added to ready queue [Q J]
time 2ms: Process J (tau 100ms) started using the CPU for 40ms burst [Q empty]
time 7ms: Process K (tau 100ms) arrived; added to ready queue [Q K]
time 9ms: Process A (tau 100ms) arrived; added to ready queue [Q AK]
time 11ms: Process H (tau 100ms) arrived; added to ready queue [Q AHK]
time 16ms: Process M (tau 100ms) arrived; added to ready queue [Q AHKM]
time 18ms: Process B (tau 100ms) arrived; added to ready queue [Q ABHKM]
time 29ms: Process O (tau 100ms) arrived; added to ready queue [Q ABHKMO]
time 42ms: Process C (tau 100ms) arrived; added to ready queue [Q ABCHKMO]
time 42ms: Process J (tau 100ms) completed a CPU burst; 9 bursts to go [Q ABCHKMO]
time 42ms: Recalculated tau from 100ms to 55ms for process J [Q ABCHKMO]
time 42ms: Process J switching out of CPU; will block on I/O until time 74ms [Q ABCHKMO]
time 46ms: Process K (tau 100ms) started using the CPU for 64ms burst [Q ABCHMO]
time 65ms: Process G (tau 100ms) arrived; added to ready queue [Q ABCGHMO]
time 68ms: Process I (tau 100ms) arrived; added to ready queue [Q ABCGHIMO]
time 74ms: Process J (tau 55ms) completed I/O; added to ready queue [Q ABCGHIJMO]
time 106ms: Process F (tau 100ms) arrived; added to ready queue [Q ABCFGHIJMO]
time 110ms: Process K (tau 100ms) completed a CPU burst; 12 bursts to go [Q ABCFGHIJMO]
time 110ms: Recalculated tau from 100ms to 73ms for process K [Q ABCFGHIJMO]
time 110ms: Process K switching out of CPU; will block on I/O until time 1072ms [Q ABCFGHIJMO]
time 114ms: Process A (tau 100ms) started using the CPU for 56ms burst [Q BCFGHIJMO]
time 122ms: Process N (tau 100ms) arrived; added to ready queue [Q BCFGHIJMNO]
time 134ms: Process E (tau 100ms) arrived; added to ready queue [Q BCEFGHIJMNO]
time 156ms: Process D (tau 100ms) arrived; added to ready queue [Q BCDEFGHIJMNO]
time 159ms: Process P (tau 100ms) arrived; added to ready queue [Q BCDEFGHIJMNOP]
time 170ms: Process A (tau 100ms) completed a CPU burst; 15 bursts to go [Q BCDEFGHIJMNOP]
time 170ms: Recalculated tau from 100ms to 67ms for process A [Q BCDEFGHIJMNOP]
time 170ms: Process A switching out of CPU; will block on I/O until time 402ms [Q BCDEFGHIJMNOP]
time 174ms: Process H (tau 100ms) started using the CPU for 96ms burst [Q BCDEFGIJMNOP]
time 189ms: Process L (tau 100ms) arrived; added to ready queue [Q BCDEFGIJLMNOP]
time 270ms: Process H (tau 100ms) completed a CPU burst; 82 bursts to go [Q BCDEFGIJLMNOP]
time 270ms: Recalculated tau from 100ms to 97ms for process H [Q BCDEFGIJLMNOP]
time 270ms: Process H switching out of CPU; will block on I/O until time 942ms [Q BCDEFGIJLMNOP]
time 274ms: Process M (tau 100ms) started using the CPU for 22ms burst [Q BCDEFGIJLNOP]
time 296ms: Process M (tau 100ms) completed a CPU burst; 47 bursts to go [Q BCDEFGIJLNOP]
time 296ms: Recalculated tau from 100ms to 42ms for process M [Q BCDEFGIJLNOP]
time 296ms: Process M switching out of CPU; will block on I/O until time 468ms [Q BCDEFGIJLNOP]
time 300ms: Process B (tau 100ms) started using the CPU for 106ms burst [Q CDEFGIJLNOP]
time 402ms: Process A (tau 67ms) completed I/O; added to ready queue [Q ACDEFGIJLNOP]
time 406ms: Process B (tau 100ms) completed a CPU burst; 20 bursts to go [Q ACDEFGIJLNOP]
time 406ms: Recalculated tau from 100ms to 105ms for process B [Q ACDEFGIJLNOP]
time 406ms: Process B switching out of CPU; will block on I/O until time 1968ms [Q ACDEFGIJLNOP]
time 410ms: Process O (tau 100ms) started using the CPU for 156ms burst [Q ACDEFGIJLNP]
time 468ms: Process M (tau 42ms) completed I/O; added to ready queue [Q ACDEFGIJLMNP]
time 566ms: Process O (tau 100ms) completed a CPU burst; 30 bursts to go [Q ACDEFGIJLMNP]
time 566ms: Recalculated tau from 100ms to 142ms for process O [Q ACDEFGIJLMNP]
time 566ms: Process O switching out of CPU; will block on I/O until time 1238ms [Q ACDEFGIJLMNP]
time 570ms: Process C (tau 100ms) started using the CPU for 94ms burst [Q ADEFGIJLMNP]
time 664ms: Process C (tau 100ms) completed a CPU burst; 3 bursts to go [Q ADEFGIJLMNP]
time 664ms: Recalculated tau from 100ms to 96ms for process C [Q ADEFGIJLMNP]
time 664ms: Process C switching out of CPU; will block on I/O until time 2246ms [Q ADEFGIJLMNP]
time 668ms: Process G (tau 100ms) started using the CPU for 70ms burst [Q ADEFIJLMNP]
time 738ms: Process G (tau 100ms) completed a CPU burst; 79 bursts to go [Q ADEFIJLMNP]
time 738ms: Recalculated tau from 100ms to 78ms for process G [Q ADEFIJLMNP]
time 738ms: Process G switching out of CPU; will block on I/O until time 1050ms [Q ADEFIJLMNP]
time 742ms: Process I (tau 100ms) started using the CPU for 220ms burst [Q ADEFJLMNP]
time 942ms: Process H (tau 97ms) completed I/O; added to ready queue [Q ADEFHJLMNP]
time 962ms: Process I (tau 100ms) completed a CPU burst; 76 bursts to go [Q ADEFHJLMNP]
time 962ms: Recalculated tau from 100ms to 190ms for process I [Q ADEFHJLMNP]
time 962ms: Process I switching out of CPU; will block on I/O until time 1154ms [Q ADEFHJLMNP]
time 966ms: Process J (tau 55ms) started using the CPU for 204ms burst [Q ADEFHLMNP]
time 4247ms: Process C terminated [Q BEHIJKN]
time 8520ms: Process L terminated [Q BDEFGIJNP]
time 9020ms: Process J terminated [Q DHKNO]
time 14001ms: Process D terminated [Q I]
time 14542ms: Process K terminated [Q empty]
time 16458ms: Process A terminated [Q BGHIMN]
time 22465ms: Process B terminated [Q FHO]
time 25034ms: Process P terminated [Q G]
time 32294ms: Process F terminated [Q HIN]
time 36145ms: Process N terminated [Q EG]
time 36830ms: Process O terminated [Q empty]
time 50385ms: Process E terminated [Q H]
time 53268ms: Process M terminated [Q empty]
time 72369ms: Process H terminated [Q empty]
time 75505ms: Process I terminated [Q empty]
time 78518ms: Process G terminated [Q empty]
time 78520ms: Simulator ended for SJF [Q empty]

time 0ms: Simulator started for SRT [Q empty]
time 0ms: Process J (tau 100ms) arrived; added to ready queue [Q J]
time 2ms: Process J (tau 100ms) started using the CPU for 40ms burst [Q empty]
time 7ms: Process K (tau 100ms) arrived; added to ready queue [Q K]
time 9ms: Process A (tau 100ms) arrived; added to ready queue [Q AK]
time 11ms: Process H (tau 100ms) arrived; added to ready queue [Q AHK]
time 16ms: Process M (tau 100ms) arrived; added to ready queue [Q AHKM]
time 18ms: Process B (tau 100ms) arrived; added to ready queue [Q ABHKM]
time 29ms: Process O (tau 100ms) arrived; added to ready queue [Q ABHKMO]
time 42ms: Process C (tau 100ms) arrived; added to ready queue [Q ABCHKMO]
time 42ms: Process J (tau 100ms) completed a CPU burst; 9 bursts to go [Q ABCHKMO]
time 42ms: Recalculated tau from 100ms to 55ms for process J [Q ABCHKMO]
time 42ms: Process J switching out of CPU; will block on I/O until time 74ms [Q ABCHKMO]
time 46ms: Process A (tau 100ms) started using the CPU for 56ms burst [Q BCHKMO]
time 65ms: Process G (tau 100ms) arrived; added to ready queue [Q BCGHKMO]
time 68ms: Process I (tau 100ms) arrived; added to ready queue [Q BCGHIKMO]
time 74ms: Process J (tau 55ms) completed I/O; added to ready queue [Q BCGHIJKMO]
time 102ms: Process A (tau 100ms) completed a CPU burst; 15 bursts to go [Q BCGHIJKMO]
time 102ms: Recalculated tau from 100ms to 67ms for process A [Q BCGHIJKMO]
time 102ms: Process A switching out of CPU; will block on I/O until time 334ms [Q BCGHIJKMO]
time 106ms: Process B (tau 100ms) started using the CPU for 106ms burst [Q CGHIJKMO]
time 106ms: Process F (tau 100ms) arrived; added to ready queue [Q CFGHIJKMO]
time 122ms: Process N (tau 100ms) arrived; added to ready queue [Q CFGHIJKMNO]
time 134ms: Process E (tau 100ms) arrived; added to ready queue [Q CEFGHIJKMNO]
time 156ms: Process D (tau 100ms) arrived; added to ready queue [Q CDEFGHIJKMNO]
time 159ms: Process P (tau 100ms) arrived; added to ready queue [Q CDEFGHIJKMNOP]
time 189ms: Process L (tau 100ms) arrived; added to ready queue [Q CDEFGHIJKLMNOP]
time 212ms: Process B (tau 100ms) completed a CPU burst; 20 bursts to go [Q CDEFGHIJKLMNOP]
time 212ms: Recalculated tau from 100ms to 105ms for process B [Q CDEFGHIJKLMNOP]
time 212ms: Process B switching out of CPU; will block on I/O until time 1774ms [Q CDEFGHIJKLMNOP]
time 216ms: Process C (tau 100ms) started using the CPU for 94ms burst [Q DEFGHIJKLMNOP]
time 310ms: Process C (tau 100ms) completed a CPU burst; 3 bursts to go [Q DEFGHIJKLMNOP]
time 310ms: Recalculated tau from 100ms to 96ms for process C [Q DEFGHIJKLMNOP]
time 310ms: Process C switching out of CPU; will block on I/O until time 1892ms [Q DEFGHIJKLMNOP]
time 314ms: Process D (tau 100ms) started using the CPU for 148ms burst [Q EFGHIJKLMNOP]
time 334ms: Process A (tau 67ms) completed I/O; added to ready queue [Q AEFGHIJKLMNOP]
time 462ms: Process D (tau 100ms) completed a CPU burst; 10 bursts to go [Q AEFGHIJKLMNOP]
time 462ms: Recalculated tau from 100ms to 136ms for process D [Q AEFGHIJKLMNOP]
time 462ms: Process D switching out of CPU; will block on I/O until time 484ms [Q AEFGHIJKLMNOP]
time 466ms: Process E (tau 100ms) started using the CPU for 152ms burst [Q AFGHIJKLMNOP]
time 484ms: Process D (tau 136ms) completed I/O; added to ready queue [Q ADFGHIJKLMNOP]
time 618ms: Process E (tau 100ms) completed a CPU burst; 54 bursts to go [Q ADFGHIJKLMNOP]
time 618ms: Recalculated tau from 100ms to 139ms for process E [Q ADFGHIJKLMNOP]
time 618ms: Process E switching out of CPU; will block on I/O until time 1080ms [Q ADFGHIJKLMNOP]
time 622ms: Process F (tau 100ms) started using the CPU for 129ms burst [Q ADGHIJKLMNOP]
time 751ms: Process F (tau 100ms) completed a CPU burst; 33 bursts to go [Q ADGHIJKLMNOP]
time 751ms: Recalculated tau from 100ms to 122ms for process F [Q ADGHIJKLMNOP]
time 751ms: Process F switching out of CPU; will block on I/O until time 1323ms [Q ADGHIJKLMNOP]
time 755ms: Process G (tau 100ms) started using the CPU for 70ms burst [Q ADHIJKLMNOP]
time 825ms: Process G (tau 100ms) completed a CPU burst; 79 bursts to go [Q ADHIJKLMNOP]
time 825ms: Recalculated tau from 100ms to 78ms for process G [Q ADHIJKLMNOP]
time 825ms: Process G switching out of CPU; will block on I/O until time 1137ms [Q ADHIJKLMNOP]
time 829ms: Process H (tau 100ms) started using the CPU for 96ms burst [Q ADIJKLMNOP]
time 925ms: Process H (tau 100ms) completed a CPU burst; 82 bursts to go [Q ADIJKLMNOP]
time 925ms: Recalculated tau from 100ms to 97ms for process H [Q ADIJKLMNOP]
time 925ms: Process H switching out of CPU; will block on I/O until time 1597ms [Q ADIJKLMNOP]
time 929ms: Process I (tau 100ms) started using the CPU for 220ms burst [Q ADJKLMNOP]
time 4505ms: Process C terminated [Q ADEFGHIJN]
time 8627ms: Process L terminated [Q EGHIJKNP]
time 8734ms: Process J terminated [Q BEGHIN]
time 13119ms: Process D terminated [Q ABFMP]
time 14772ms: Process K terminated [Q empty]
time 15834ms: Process A terminated [Q BEFGMO]
time 22968ms: Process B terminated [Q EGNOP]
time 24413ms: Process P terminated [Q empty]
time 32700ms: Process F terminated [Q HO]
time 35415ms: Process N terminated [Q empty]
time 36710ms: Process O terminated [Q H]
time 50479ms: Process E terminated [Q G]
time 52115ms: Process M terminated [Q empty]
time 72564ms: Process H terminated [Q empty]
time 74573ms: Process I terminated [Q empty]
time 78791ms: Process G terminated [Q empty]
time 78793ms: Simulator ended for SRT [Q empty]

time 0ms: Simulator started for RR with time slice 64ms [Q empty]
time 0ms: Process J arrived; added to ready queue [Q J]
time 2ms: Process J started using the CPU for 40ms burst [Q empty]
time 7ms: Process K arrived; added to ready queue [Q K]
time 9ms: Process A arrived; added to ready queue [Q AK]
time 11ms: Process H arrived; added to ready queue [Q AHK]
time 16ms: Process M arrived; added to ready queue [Q AHKM]
time 18ms: Process B arrived; added to ready queue [Q ABHKM]
time 29ms: Process O arrived; added to ready queue [Q ABHKMO]
time 42ms: Process J completed a CPU burst; 9 bursts to go [Q ABHKMO]
time 42ms: Process J switching out of CPU; will block on I/O until time 74ms [Q ABHKMO]
time 42ms: Process C arrived; added to ready queue [Q ABCHKMO]
time 46ms: Process K started using the CPU for 64ms burst [Q ABCHMO]
time 65ms: Process G arrived; added to ready queue [Q ABCGHMO]
time 68ms: Process I arrived; added to ready queue [Q ABCGHIMO]
time 74ms: Process J completed I/O; added to ready queue [Q ABCGHIJMO]
time 106ms: Process F arrived; added to ready queue [Q ABCFGHIJMO]
time 110ms: Process K completed a CPU burst; 12 bursts to go [Q ABCFGHIJMO]
time 110ms: Process K switching out of CPU; will block on I/O until time 1072ms [Q ABCFGHIJMO]
time 114ms: Process A started using the CPU for 56ms burst [Q BCFGHIJMO]
time 122ms: Process N arrived; added to ready queue [Q BCFGHIJMNO]
time 134ms: Process E arrived; added to ready queue [Q BCEFGHIJMNO]
time 156ms: Process D arrived; added to ready queue [Q BCDEFGHIJMNO]
time 159ms: Process P arrived; added to ready queue [Q BCDEFGHIJMNOP]
time 170ms: Process A completed a CPU burst; 15 bursts to go [Q BCDEFGHIJMNOP]
time 170ms: Process A switching out of CPU; will block on I/O until time 402ms [Q BCDEFGHIJMNOP]
time 174ms: Process H started using the CPU for 96ms burst [Q BCDEFGIJMNOP]
time 189ms: Process L arrived; added to ready queue [Q BCDEFGIJLMNOP]
time 238ms: Time slice expired; process H preempted with 32ms to go [Q BCDEFGIJLMNOP]
time 242ms: Process M started using the CPU for 22ms burst [Q BCDEFGHIJLNOP]
time 264ms: Process M completed a CPU burst; 47 bursts to go [Q BCDEFGHIJLNOP]
time 264ms: Process M switching out of CPU; will block on I/O until time 436ms [Q BCDEFGHIJLNOP]
time 268ms: Process B started using the CPU for 106ms burst [Q CDEFGHIJLNOP]
time 332ms: Time slice expired; process B preempted with 42ms to go [Q CDEFGHIJLNOP]
time 336ms: Process O started using the CPU for 156ms burst [Q BCDEFGHIJLNP]
time 400ms: Time slice expired; process O preempted with 92ms to go [Q BCDEFGHIJLNP]
time 402ms: Process A completed I/O; added to ready queue [Q ABCDEFGHIJLNOP]
time 404ms: Process C started using the CPU for 94ms burst [Q ABDEFGHIJLNOP]
time 436ms: Process M completed I/O; added to ready queue [Q ABDEFGHIJLMNOP]
time 468ms: Time slice expired; process C preempted with 30ms to go [Q ABDEFGHIJLMNOP]
time 472ms: Process G started using the CPU for 70ms burst [Q ABCDEFHIJLMNOP]
time 536ms: Time slice expired; process G preempted with 6ms to go [Q ABCDEFHIJLMNOP]
time 540ms: Process I started using the CPU for 220ms burst [Q ABCDEFGHJLMNOP]
time 604ms: Time slice expired; process I preempted with 156ms to go [Q ABCDEFGHJLMNOP]
time 608ms: Process J started using the CPU for 204ms burst [Q ABCDEFGHILMNOP]
time 672ms: Time slice expired; process J preempted with 140ms to go [Q ABCDEFGHILMNOP]
time 676ms: Process F started using the CPU for 129ms burst [Q ABCDEGHIJLMNOP]
time 740ms: Time slice expired; process F preempted with 65ms to go [Q ABCDEGHIJLMNOP]
time 744ms: Process N started using the CPU for 213ms burst [Q ABCDEFGHIJLMOP]
time 808ms: Time slice expired; process N preempted with 149ms to go [Q ABCDEFGHIJLMOP]
time 812ms: Process E started using the CPU for 152ms burst [Q ABCDFGHIJLMNOP]
time 876ms: Time slice expired; process E preempted with 88ms to go [Q ABCDFGHIJLMNOP]
time 880ms: Process D started using the CPU for 148ms burst [Q ABCEFGHIJLMNOP]
time 944ms: Time slice expired; process D preempted with 84ms to go [Q ABCEFGHIJLMNOP]
time 948ms: Process P started using the CPU for 4ms burst [Q ABCDEFGHIJLMNO]
time 952ms: Process P completed a CPU burst; 15 bursts to go [Q ABCDEFGHIJLMNO]
time 952ms: Process P switching out of CPU; will block on I/O until time 2804ms [Q ABCDEFGHIJLMNO]
time 956ms: Process L started using the CPU for 135ms burst [Q ABCDEFGHIJMNO]
time 5491ms: Process C terminated [Q ABEFKN]
time 9414ms: Process L terminated [Q AFGHJMN]
time 9779ms: Process J terminated [Q FO]
time 13502ms: Process D terminated [Q EFN]
time 13910ms: Process K terminated [Q BFM]
time 16279ms: Process A terminated [Q BMO]
time 25067ms: Process B terminated [Q GHM]
time 25242ms: Process P terminated [Q M]
time 33577ms: Process F terminated [Q HM]
time 36707ms: Process O terminated [Q EH]
time 37187ms: Process N terminated [Q G]
time 51168ms: Process E terminated [Q empty]
time 53339ms: Process M terminated [Q empty]
time 72726ms: Process H terminated [Q I]
time 76392ms: Process I terminated [Q empty]
time 77577ms: Process G terminated [Q empty]
time 77579ms: Simulator ended for RR [Q empty]
