Process A (arrival time 9 ms) 16 CPU bursts (tau 100ms)
Process B (arrival time 18 ms) 21 CPU bursts (tau 100ms)
Process C (arrival time 42 ms) 4 CPU bursts (tau 100ms)
Process D (arrival time 156 ms) 11 CPU bursts (tau 100ms)
Process E (arrival time 134 ms) 55 CPU bursts (tau 100ms)
Process F (arrival time 106 ms) 34 CPU bursts (tau 100ms)
Process G (arrival time 65 ms) 80 CPU bursts (tau 100ms)
Process H (arrival time 11 ms) 83 CPU bursts (tau 100ms)
Process I (arrival time 68 ms) 77 CPU bursts (tau 100ms)
Process J (arrival time 0 ms) 10 CPU bursts (tau 100ms)
Process K (arrival time 7 ms) 13 CPU bursts (tau 100ms)
Process L (arrival time 189 ms) 7 CPU bursts (tau 100ms)
Process M (arrival time 16 ms) 48 CPU bursts (tau 100ms)
Process N (arrival time 122 ms) 31 CPU bursts (tau 100ms)
Process O (arrival time 29 ms) 31 CPU bursts (tau 100ms)
Process P (arrival time 159 ms) 16 CPU bursts (tau 100ms)


time 0ms: Simulator started for SJF [Q empty]
time 0ms: Process A arrived; added to ready queue [Q A]
time 0ms: Process B arrived; added to ready queue [Q A B]
time 0ms: Process C arrived; added to ready queue [Q A B C]
time 0ms: Process D arrived; added to ready queue [Q A B C D]
time 0ms: Process E arrived; added to ready queue [Q A B C D E]
time 0ms: Process F arrived; added to ready queue [Q A B C D E F]
time 0ms: Process G arrived; added to ready queue [Q A B C D E F G]
time 0ms: Process H arrived; added to ready queue [Q A B C D E F G H]
time 0ms: Process I arrived; added to ready queue [Q A B C D E F G H I]
time 0ms: Process J arrived; added to ready queue [Q A B C D E F G H I J]
time 0ms: Process K arrived; added to ready queue [Q A B C D E F G H I J K]
time 0ms: Process L arrived; added to ready queue [Q A B C D E F G H I J K L]
time 0ms: Process M arrived; added to ready queue [Q A B C D E F G H I J K L M]
time 0ms: Process N arrived; added to ready queue [Q A B C D E F G H I J K L M N]
time 0ms: Process O arrived; added to ready queue [Q A B C D E F G H I J K L M N O]
time 0ms: Process P arrived; added to ready queue [Q A B C D E F G H I J K L M N O P]
process: aval; of100
process: bval; of100
process: cval; of100
process: dval; of100
process: eval; of100
process: fval; of100
process: gval; of100
process: hval; of100
process: ival; of100
process: jval; of100
process: kval; of100
process: lval; of100
process: mval; of100
process: nval; of100
process: oval; of100
process: pval; of100
