Process A (arrival time 9 ms) 16 CPU bursts (tau 100ms)
Process B (arrival time 18 ms) 21 CPU bursts (tau 100ms)
Process C (arrival time 42 ms) 4 CPU bursts (tau 100ms)
Process D (arrival time 156 ms) 11 CPU bursts (tau 100ms)
Process E (arrival time 134 ms) 55 CPU bursts (tau 100ms)
Process F (arrival time 106 ms) 34 CPU bursts (tau 100ms)
Process G (arrival time 65 ms) 80 CPU bursts (tau 100ms)
Process H (arrival time 11 ms) 83 CPU bursts (tau 100ms)
Process I (arrival time 68 ms) 77 CPU bursts (tau 100ms)
Process J (arrival time 0 ms) 10 CPU bursts (tau 100ms)
Process K (arrival time 7 ms) 13 CPU bursts (tau 100ms)
Process L (arrival time 189 ms) 7 CPU bursts (tau 100ms)
Process M (arrival time 16 ms) 48 CPU bursts (tau 100ms)
Process N (arrival time 122 ms) 31 CPU bursts (tau 100ms)
Process O (arrival time 29 ms) 31 CPU bursts (tau 100ms)
Process P (arrival time 159 ms) 16 CPU bursts (tau 100ms)


time 0ms: Simulator started for FCFS [Q empty]
time 0ms: Process J arrived; added to ready queue [Q J]
time 2ms: Process J started using the CPU for 40ms burst [Q empty]
time 7ms: Process K arrived; added to ready queue [Q K]
time 9ms: Process A arrived; added to ready queue [Q K A]
time 11ms: Process H arrived; added to ready queue [Q K A H]
time 16ms: Process M arrived; added to ready queue [Q K A H M]
time 18ms: Process B arrived; added to ready queue [Q K A H M B]
time 29ms: Process O arrived; added to ready queue [Q K A H M B O]
time 42ms: Process C arrived; added to ready queue [Q K A H M B O C]
time 42ms: Process J completed a CPU burst; 9 bursts to go [Q K A H M B O C]
time 42ms: Process J switching out of CPU; will block on I/O until time 74ms [Q K A H M B O C]
time 46ms: Process K started using the CPU for 64ms burst [Q A H M B O C]
time 65ms: Process G arrived; added to ready queue [Q A H M B O C G]
time 68ms: Process I arrived; added to ready queue [Q A H M B O C G I]
time 74ms: Process J completed I/O; added to ready queue [Q A H M B O C G I J]
time 106ms: Process F arrived; added to ready queue [Q A H M B O C G I J F]
time 110ms: Process K completed a CPU burst; 12 bursts to go [Q A H M B O C G I J F]
time 110ms: Process K switching out of CPU; will block on I/O until time 1072ms [Q A H M B O C G I J F]
time 114ms: Process A started using the CPU for 56ms burst [Q H M B O C G I J F]
time 122ms: Process N arrived; added to ready queue [Q H M B O C G I J F N]
time 134ms: Process E arrived; added to ready queue [Q H M B O C G I J F N E]
time 156ms: Process D arrived; added to ready queue [Q H M B O C G I J F N E D]
time 159ms: Process P arrived; added to ready queue [Q H M B O C G I J F N E D P]
time 170ms: Process A completed a CPU burst; 15 bursts to go [Q H M B O C G I J F N E D P]
time 170ms: Process A switching out of CPU; will block on I/O until time 402ms [Q H M B O C G I J F N E D P]
time 174ms: Process H started using the CPU for 96ms burst [Q M B O C G I J F N E D P]
time 189ms: Process L arrived; added to ready queue [Q M B O C G I J F N E D P L]
time 270ms: Process H completed a CPU burst; 82 bursts to go [Q M B O C G I J F N E D P L]
time 270ms: Process H switching out of CPU; will block on I/O until time 942ms [Q M B O C G I J F N E D P L]
time 274ms: Process M started using the CPU for 22ms burst [Q B O C G I J F N E D P L]
time 296ms: Process M completed a CPU burst; 47 bursts to go [Q B O C G I J F N E D P L]
time 296ms: Process M switching out of CPU; will block on I/O until time 468ms [Q B O C G I J F N E D P L]
time 300ms: Process B started using the CPU for 106ms burst [Q O C G I J F N E D P L]
time 402ms: Process A completed I/O; added to ready queue [Q O C G I J F N E D P L A]
time 406ms: Process B completed a CPU burst; 20 bursts to go [Q O C G I J F N E D P L A]
time 406ms: Process B switching out of CPU; will block on I/O until time 1968ms [Q O C G I J F N E D P L A]
time 410ms: Process O started using the CPU for 156ms burst [Q C G I J F N E D P L A]
time 468ms: Process M completed I/O; added to ready queue [Q C G I J F N E D P L A M]
time 566ms: Process O completed a CPU burst; 30 bursts to go [Q C G I J F N E D P L A M]
time 566ms: Process O switching out of CPU; will block on I/O until time 1238ms [Q C G I J F N E D P L A M]
time 570ms: Process C started using the CPU for 94ms burst [Q G I J F N E D P L A M]
time 664ms: Process C completed a CPU burst; 3 bursts to go [Q G I J F N E D P L A M]
time 664ms: Process C switching out of CPU; will block on I/O until time 2246ms [Q G I J F N E D P L A M]
time 668ms: Process G started using the CPU for 70ms burst [Q I J F N E D P L A M]
time 738ms: Process G completed a CPU burst; 79 bursts to go [Q I J F N E D P L A M]
time 738ms: Process G switching out of CPU; will block on I/O until time 1050ms [Q I J F N E D P L A M]
time 742ms: Process I started using the CPU for 220ms burst [Q J F N E D P L A M]
time 942ms: Process H completed I/O; added to ready queue [Q J F N E D P L A M H]
time 962ms: Process I completed a CPU burst; 76 bursts to go [Q J F N E D P L A M H]
time 962ms: Process I switching out of CPU; will block on I/O until time 1154ms [Q J F N E D P L A M H]
time 966ms: Process J started using the CPU for 204ms burst [Q F N E D P L A M H]
time 1050ms: Process G completed I/O; added to ready queue [Q F N E D P L A M H G]
time 1072ms: Process K completed I/O; added to ready queue [Q F N E D P L A M H G K]
time 1154ms: Process I completed I/O; added to ready queue [Q F N E D P L A M H G K I]
time 1170ms: Process J completed a CPU burst; 8 bursts to go [Q F N E D P L A M H G K I]
time 1170ms: Process J switching out of CPU; will block on I/O until time 1872ms [Q F N E D P L A M H G K I]
time 1174ms: Process F started using the CPU for 129ms burst [Q N E D P L A M H G K I]
time 1238ms: Process O completed I/O; added to ready queue [Q N E D P L A M H G K I O]
time 1303ms: Process F completed a CPU burst; 33 bursts to go [Q N E D P L A M H G K I O]
time 1303ms: Process F switching out of CPU; will block on I/O until time 1875ms [Q N E D P L A M H G K I O]
time 1307ms: Process N started using the CPU for 213ms burst [Q E D P L A M H G K I O]
time 1520ms: Process N completed a CPU burst; 30 bursts to go [Q E D P L A M H G K I O]
time 1520ms: Process N switching out of CPU; will block on I/O until time 1672ms [Q E D P L A M H G K I O]
time 1524ms: Process E started using the CPU for 152ms burst [Q D P L A M H G K I O]
time 1672ms: Process N completed I/O; added to ready queue [Q D P L A M H G K I O N]
time 1676ms: Process E completed a CPU burst; 54 bursts to go [Q D P L A M H G K I O N]
time 1676ms: Process E switching out of CPU; will block on I/O until time 2138ms [Q D P L A M H G K I O N]
time 1680ms: Process D started using the CPU for 148ms burst [Q P L A M H G K I O N]
time 1828ms: Process D completed a CPU burst; 10 bursts to go [Q P L A M H G K I O N]
time 1828ms: Process D switching out of CPU; will block on I/O until time 1850ms [Q P L A M H G K I O N]
time 1832ms: Process P started using the CPU for 4ms burst [Q L A M H G K I O N]
time 1836ms: Process P completed a CPU burst; 15 bursts to go [Q L A M H G K I O N]
time 1836ms: Process P switching out of CPU; will block on I/O until time 3688ms [Q L A M H G K I O N]
time 1840ms: Process L started using the CPU for 135ms burst [Q A M H G K I O N]
time 1850ms: Process D completed I/O; added to ready queue [Q A M H G K I O N D]
time 1872ms: Process J completed I/O; added to ready queue [Q A M H G K I O N D J]
time 1875ms: Process F completed I/O; added to ready queue [Q A M H G K I O N D J F]
time 1968ms: Process B completed I/O; added to ready queue [Q A M H G K I O N D J F B]
time 1975ms: Process L completed a CPU burst; 6 bursts to go [Q A M H G K I O N D J F B]
time 1975ms: Process L switching out of CPU; will block on I/O until time 2717ms [Q A M H G K I O N D J F B]
time 1979ms: Process A started using the CPU for 60ms burst [Q M H G K I O N D J F B]
time 2039ms: Process A completed a CPU burst; 14 bursts to go [Q M H G K I O N D J F B]
time 2039ms: Process A switching out of CPU; will block on I/O until time 3571ms [Q M H G K I O N D J F B]
time 2043ms: Process M started using the CPU for 93ms burst [Q H G K I O N D J F B]
time 2136ms: Process M completed a CPU burst; 46 bursts to go [Q H G K I O N D J F B]
time 2136ms: Process M switching out of CPU; will block on I/O until time 2558ms [Q H G K I O N D J F B]
time 2138ms: Process E completed I/O; added to ready queue [Q H G K I O N D J F B E]
time 2140ms: Process H started using the CPU for 48ms burst [Q G K I O N D J F B E]
time 2188ms: Process H completed a CPU burst; 81 bursts to go [Q G K I O N D J F B E]
time 2188ms: Process H switching out of CPU; will block on I/O until time 2410ms [Q G K I O N D J F B E]
time 2192ms: Process G started using the CPU for 40ms burst [Q K I O N D J F B E]
time 2232ms: Process G completed a CPU burst; 78 bursts to go [Q K I O N D J F B E]
time 2232ms: Process G switching out of CPU; will block on I/O until time 2294ms [Q K I O N D J F B E]
time 2236ms: Process K started using the CPU for 56ms burst [Q I O N D J F B E]
time 2246ms: Process C completed I/O; added to ready queue [Q I O N D J F B E C]
time 2292ms: Process K completed a CPU burst; 11 bursts to go [Q I O N D J F B E C]
time 2292ms: Process K switching out of CPU; will block on I/O until time 3024ms [Q I O N D J F B E C]
time 2294ms: Process G completed I/O; added to ready queue [Q I O N D J F B E C G]
time 2296ms: Process I started using the CPU for 16ms burst [Q O N D J F B E C G]
time 2312ms: Process I completed a CPU burst; 75 bursts to go [Q O N D J F B E C G]
time 2312ms: Process I switching out of CPU; will block on I/O until time 4074ms [Q O N D J F B E C G]
time 2316ms: Process O started using the CPU for 106ms burst [Q N D J F B E C G]
time 2410ms: Process H completed I/O; added to ready queue [Q N D J F B E C G H]
time 2422ms: Process O completed a CPU burst; 29 bursts to go [Q N D J F B E C G H]
time 2422ms: Process O switching out of CPU; will block on I/O until time 4914ms [Q N D J F B E C G H]
time 2426ms: Process N started using the CPU for 132ms burst [Q D J F B E C G H]
time 2558ms: Process M completed I/O; added to ready queue [Q D J F B E C G H M]
time 2558ms: Process N completed a CPU burst; 29 bursts to go [Q D J F B E C G H M]
time 2558ms: Process N switching out of CPU; will block on I/O until time 4160ms [Q D J F B E C G H M]
time 2562ms: Process D started using the CPU for 211ms burst [Q J F B E C G H M]
time 2717ms: Process L completed I/O; added to ready queue [Q J F B E C G H M L]
time 2773ms: Process D completed a CPU burst; 9 bursts to go [Q J F B E C G H M L]
time 2773ms: Process D switching out of CPU; will block on I/O until time 4915ms [Q J F B E C G H M L]
time 2777ms: Process J started using the CPU for 28ms burst [Q F B E C G H M L]
time 2805ms: Process J completed a CPU burst; 7 bursts to go [Q F B E C G H M L]
time 2805ms: Process J switching out of CPU; will block on I/O until time 3027ms [Q F B E C G H M L]
time 2809ms: Process F started using the CPU for 39ms burst [Q B E C G H M L]
time 2848ms: Process F completed a CPU burst; 32 bursts to go [Q B E C G H M L]
time 2848ms: Process F switching out of CPU; will block on I/O until time 3500ms [Q B E C G H M L]
time 2852ms: Process B started using the CPU for 198ms burst [Q E C G H M L]
time 3024ms: Process K completed I/O; added to ready queue [Q E C G H M L K]
time 3027ms: Process J completed I/O; added to ready queue [Q E C G H M L K J]
time 3050ms: Process B completed a CPU burst; 19 bursts to go [Q E C G H M L K J]
time 3050ms: Process B switching out of CPU; will block on I/O until time 4182ms [Q E C G H M L K J]
time 3054ms: Process E started using the CPU for 44ms burst [Q C G H M L K J]
time 3098ms: Process E completed a CPU burst; 53 bursts to go [Q C G H M L K J]
time 3098ms: Process E switching out of CPU; will block on I/O until time 3660ms [Q C G H M L K J]
time 3102ms: Process C started using the CPU for 117ms burst [Q G H M L K J]
time 3219ms: Process C completed a CPU burst; 2 bursts to go [Q G H M L K J]
time 3219ms: Process C switching out of CPU; will block on I/O until time 3391ms [Q G H M L K J]
time 3223ms: Process G started using the CPU for 65ms burst [Q H M L K J]
time 3288ms: Process G completed a CPU burst; 77 bursts to go [Q H M L K J]
time 3288ms: Process G switching out of CPU; will block on I/O until time 3730ms [Q H M L K J]
time 3292ms: Process H started using the CPU for 72ms burst [Q M L K J]
time 3364ms: Process H completed a CPU burst; 80 bursts to go [Q M L K J]
time 3364ms: Process H switching out of CPU; will block on I/O until time 3786ms [Q M L K J]
time 3368ms: Process M started using the CPU for 79ms burst [Q L K J]
time 3391ms: Process C completed I/O; added to ready queue [Q L K J C]
time 3447ms: Process M completed a CPU burst; 45 bursts to go [Q L K J C]
time 3447ms: Process M switching out of CPU; will block on I/O until time 4589ms [Q L K J C]
time 3451ms: Process L started using the CPU for 4ms burst [Q K J C]
time 3455ms: Process L completed a CPU burst; 5 bursts to go [Q K J C]
time 3455ms: Process L switching out of CPU; will block on I/O until time 3877ms [Q K J C]
time 3459ms: Process K started using the CPU for 6ms burst [Q J C]
time 3465ms: Process K completed a CPU burst; 10 bursts to go [Q J C]
time 3465ms: Process K switching out of CPU; will block on I/O until time 4167ms [Q J C]
time 3469ms: Process J started using the CPU for 120ms burst [Q C]
time 3500ms: Process F completed I/O; added to ready queue [Q C F]
time 3571ms: Process A completed I/O; added to ready queue [Q C F A]
time 3589ms: Process J completed a CPU burst; 6 bursts to go [Q C F A]
time 3589ms: Process J switching out of CPU; will block on I/O until time 4151ms [Q C F A]
time 3593ms: Process C started using the CPU for 85ms burst [Q F A]
time 3660ms: Process E completed I/O; added to ready queue [Q F A E]
time 3678ms: Process C completed a CPU burst; 1 bursts to go [Q F A E]
time 3678ms: Process C switching out of CPU; will block on I/O until time 3890ms [Q F A E]
time 3682ms: Process F started using the CPU for 195ms burst [Q A E]
time 3688ms: Process P completed I/O; added to ready queue [Q A E P]
time 3730ms: Process G completed I/O; added to ready queue [Q A E P G]
time 3786ms: Process H completed I/O; added to ready queue [Q A E P G H]
time 3877ms: Process L completed I/O; added to ready queue [Q A E P G H L]
time 3877ms: Process F completed a CPU burst; 31 bursts to go [Q A E P G H L]
time 3877ms: Process F switching out of CPU; will block on I/O until time 3889ms [Q A E P G H L]
time 3881ms: Process A started using the CPU for 39ms burst [Q E P G H L]
time 3889ms: Process F completed I/O; added to ready queue [Q E P G H L F]
time 3890ms: Process C completed I/O; added to ready queue [Q E P G H L F C]
time 3920ms: Process A completed a CPU burst; 13 bursts to go [Q E P G H L F C]
time 3920ms: Process A switching out of CPU; will block on I/O until time 4422ms [Q E P G H L F C]
time 3924ms: Process E started using the CPU for 2ms burst [Q P G H L F C]
time 3926ms: Process E completed a CPU burst; 52 bursts to go [Q P G H L F C]
time 3926ms: Process E switching out of CPU; will block on I/O until time 4178ms [Q P G H L F C]
time 3930ms: Process P started using the CPU for 52ms burst [Q G H L F C]
time 3982ms: Process P completed a CPU burst; 14 bursts to go [Q G H L F C]
time 3982ms: Process P switching out of CPU; will block on I/O until time 5074ms [Q G H L F C]
time 3986ms: Process G started using the CPU for 13ms burst [Q H L F C]
time 3999ms: Process G completed a CPU burst; 76 bursts to go [Q H L F C]
time 3999ms: Process G switching out of CPU; will block on I/O until time 4381ms [Q H L F C]
time 4003ms: Process H started using the CPU for 12ms burst [Q L F C]
time 4015ms: Process H completed a CPU burst; 79 bursts to go [Q L F C]
time 4015ms: Process H switching out of CPU; will block on I/O until time 4147ms [Q L F C]
time 4019ms: Process L started using the CPU for 69ms burst [Q F C]
time 4074ms: Process I completed I/O; added to ready queue [Q F C I]
time 4088ms: Process L completed a CPU burst; 4 bursts to go [Q F C I]
time 4088ms: Process L switching out of CPU; will block on I/O until time 5040ms [Q F C I]
time 4092ms: Process F started using the CPU for 72ms burst [Q C I]
time 4147ms: Process H completed I/O; added to ready queue [Q C I H]
time 4151ms: Process J completed I/O; added to ready queue [Q C I H J]
time 4160ms: Process N completed I/O; added to ready queue [Q C I H J N]
time 4164ms: Process F completed a CPU burst; 30 bursts to go [Q C I H J N]
time 4164ms: Process F switching out of CPU; will block on I/O until time 4426ms [Q C I H J N]
time 4168ms: Process C started using the CPU for 79ms burst [Q I H J N]
time 4167ms: Process K completed I/O; added to ready queue [Q I H J N K]
time 4178ms: Process E completed I/O; added to ready queue [Q I H J N K E]
time 4182ms: Process B completed I/O; added to ready queue [Q I H J N K E B]
time 4247ms: Process C terminated [Q I H J N K E B]
time 4251ms: Process I started using the CPU for 26ms burst [Q H J N K E B]
time 4277ms: Process I completed a CPU burst; 74 bursts to go [Q H J N K E B]
time 4277ms: Process I switching out of CPU; will block on I/O until time 4909ms [Q H J N K E B]
time 4281ms: Process H started using the CPU for 41ms burst [Q J N K E B]
time 4322ms: Process H completed a CPU burst; 78 bursts to go [Q J N K E B]
time 4322ms: Process H switching out of CPU; will block on I/O until time 4534ms [Q J N K E B]
time 4326ms: Process J started using the CPU for 31ms burst [Q N K E B]
time 4357ms: Process J completed a CPU burst; 5 bursts to go [Q N K E B]
time 4357ms: Process J switching out of CPU; will block on I/O until time 5219ms [Q N K E B]
time 4361ms: Process N started using the CPU for 17ms burst [Q K E B]
time 4378ms: Process N completed a CPU burst; 28 bursts to go [Q K E B]
time 4378ms: Process N switching out of CPU; will block on I/O until time 5130ms [Q K E B]
time 4382ms: Process K started using the CPU for 6ms burst [Q E B]
time 4381ms: Process G completed I/O; added to ready queue [Q E B G]
time 4388ms: Process K completed a CPU burst; 9 bursts to go [Q E B G]
time 4388ms: Process K switching out of CPU; will block on I/O until time 5140ms [Q E B G]
time 4392ms: Process E started using the CPU for 42ms burst [Q B G]
time 4422ms: Process A completed I/O; added to ready queue [Q B G A]
time 4426ms: Process F completed I/O; added to ready queue [Q B G A F]
time 4434ms: Process E completed a CPU burst; 51 bursts to go [Q B G A F]
time 4434ms: Process E switching out of CPU; will block on I/O until time 4486ms [Q B G A F]
time 4438ms: Process B started using the CPU for 208ms burst [Q G A F]
time 4486ms: Process E completed I/O; added to ready queue [Q G A F E]
time 4534ms: Process H completed I/O; added to ready queue [Q G A F E H]
time 4589ms: Process M completed I/O; added to ready queue [Q G A F E H M]
time 4646ms: Process B completed a CPU burst; 18 bursts to go [Q G A F E H M]
time 4646ms: Process B switching out of CPU; will block on I/O until time 6268ms [Q G A F E H M]
time 4650ms: Process G started using the CPU for 128ms burst [Q A F E H M]
time 4778ms: Process G completed a CPU burst; 75 bursts to go [Q A F E H M]
time 4778ms: Process G switching out of CPU; will block on I/O until time 7000ms [Q A F E H M]
time 4782ms: Process A started using the CPU for 47ms burst [Q F E H M]
time 4829ms: Process A completed a CPU burst; 12 bursts to go [Q F E H M]
time 4829ms: Process A switching out of CPU; will block on I/O until time 4851ms [Q F E H M]
time 4833ms: Process F started using the CPU for 8ms burst [Q E H M]
time 4841ms: Process F completed a CPU burst; 29 bursts to go [Q E H M]
time 4841ms: Process F switching out of CPU; will block on I/O until time 5173ms [Q E H M]
time 4845ms: Process E started using the CPU for 108ms burst [Q H M]
time 4851ms: Process A completed I/O; added to ready queue [Q H M A]
time 4909ms: Process I completed I/O; added to ready queue [Q H M A I]
time 4914ms: Process O completed I/O; added to ready queue [Q H M A I O]
time 4915ms: Process D completed I/O; added to ready queue [Q H M A I O D]
time 4953ms: Process E completed a CPU burst; 50 bursts to go [Q H M A I O D]
time 4953ms: Process E switching out of CPU; will block on I/O until time 5045ms [Q H M A I O D]
time 4957ms: Process H started using the CPU for 160ms burst [Q M A I O D]
time 5040ms: Process L completed I/O; added to ready queue [Q M A I O D L]
time 5045ms: Process E completed I/O; added to ready queue [Q M A I O D L E]
time 5074ms: Process P completed I/O; added to ready queue [Q M A I O D L E P]
time 5117ms: Process H completed a CPU burst; 77 bursts to go [Q M A I O D L E P]
time 5117ms: Process H switching out of CPU; will block on I/O until time 5719ms [Q M A I O D L E P]
time 5121ms: Process M started using the CPU for 18ms burst [Q A I O D L E P]
time 5130ms: Process N completed I/O; added to ready queue [Q A I O D L E P N]
time 5139ms: Process M completed a CPU burst; 44 bursts to go [Q A I O D L E P N]
time 5139ms: Process M switching out of CPU; will block on I/O until time 7111ms [Q A I O D L E P N]
time 5140ms: Process K completed I/O; added to ready queue [Q A I O D L E P N K]
time 5143ms: Process A started using the CPU for 137ms burst [Q I O D L E P N K]
time 5173ms: Process F completed I/O; added to ready queue [Q I O D L E P N K F]
time 5219ms: Process J completed I/O; added to ready queue [Q I O D L E P N K F J]
time 5280ms: Process A completed a CPU burst; 11 bursts to go [Q I O D L E P N K F J]
time 5280ms: Process A switching out of CPU; will block on I/O until time 5522ms [Q I O D L E P N K F J]
time 5284ms: Process I started using the CPU for 45ms burst [Q O D L E P N K F J]
time 5329ms: Process I completed a CPU burst; 73 bursts to go [Q O D L E P N K F J]
time 5329ms: Process I switching out of CPU; will block on I/O until time 5631ms [Q O D L E P N K F J]
time 5333ms: Process O started using the CPU for 57ms burst [Q D L E P N K F J]
time 5390ms: Process O completed a CPU burst; 28 bursts to go [Q D L E P N K F J]
time 5390ms: Process O switching out of CPU; will block on I/O until time 5762ms [Q D L E P N K F J]
time 5394ms: Process D started using the CPU for 9ms burst [Q L E P N K F J]
time 5403ms: Process D completed a CPU burst; 8 bursts to go [Q L E P N K F J]
time 5403ms: Process D switching out of CPU; will block on I/O until time 5785ms [Q L E P N K F J]
time 5407ms: Process L started using the CPU for 25ms burst [Q E P N K F J]
time 5432ms: Process L completed a CPU burst; 3 bursts to go [Q E P N K F J]
time 5432ms: Process L switching out of CPU; will block on I/O until time 6624ms [Q E P N K F J]
time 5436ms: Process E started using the CPU for 6ms burst [Q P N K F J]
time 5442ms: Process E completed a CPU burst; 49 bursts to go [Q P N K F J]
time 5442ms: Process E switching out of CPU; will block on I/O until time 5764ms [Q P N K F J]
time 5446ms: Process P started using the CPU for 56ms burst [Q N K F J]
time 5502ms: Process P completed a CPU burst; 13 bursts to go [Q N K F J]
time 5502ms: Process P switching out of CPU; will block on I/O until time 6714ms [Q N K F J]
time 5506ms: Process N started using the CPU for 71ms burst [Q K F J]
time 5522ms: Process A completed I/O; added to ready queue [Q K F J A]
time 5577ms: Process N completed a CPU burst; 27 bursts to go [Q K F J A]
time 5577ms: Process N switching out of CPU; will block on I/O until time 7519ms [Q K F J A]
time 5581ms: Process K started using the CPU for 157ms burst [Q F J A]
time 5631ms: Process I completed I/O; added to ready queue [Q F J A I]
time 5719ms: Process H completed I/O; added to ready queue [Q F J A I H]
time 5738ms: Process K completed a CPU burst; 8 bursts to go [Q F J A I H]
time 5738ms: Process K switching out of CPU; will block on I/O until time 5900ms [Q F J A I H]
time 5742ms: Process F started using the CPU for 230ms burst [Q J A I H]
time 5762ms: Process O completed I/O; added to ready queue [Q J A I H O]
time 5764ms: Process E completed I/O; added to ready queue [Q J A I H O E]
time 5785ms: Process D completed I/O; added to ready queue [Q J A I H O E D]
time 5900ms: Process K completed I/O; added to ready queue [Q J A I H O E D K]
time 5972ms: Process F completed a CPU burst; 28 bursts to go [Q J A I H O E D K]
time 5972ms: Process F switching out of CPU; will block on I/O until time 6004ms [Q J A I H O E D K]
time 5976ms: Process J started using the CPU for 32ms burst [Q A I H O E D K]
time 6004ms: Process F completed I/O; added to ready queue [Q A I H O E D K F]
time 6008ms: Process J completed a CPU burst; 4 bursts to go [Q A I H O E D K F]
time 6008ms: Process J switching out of CPU; will block on I/O until time 6140ms [Q A I H O E D K F]
time 6012ms: Process A started using the CPU for 64ms burst [Q I H O E D K F]
time 6076ms: Process A completed a CPU burst; 10 bursts to go [Q I H O E D K F]
time 6076ms: Process A switching out of CPU; will block on I/O until time 6228ms [Q I H O E D K F]
time 6080ms: Process I started using the CPU for 38ms burst [Q H O E D K F]
time 6118ms: Process I completed a CPU burst; 72 bursts to go [Q H O E D K F]
time 6118ms: Process I switching out of CPU; will block on I/O until time 6700ms [Q H O E D K F]
time 6122ms: Process H started using the CPU for 28ms burst [Q O E D K F]
time 6140ms: Process J completed I/O; added to ready queue [Q O E D K F J]
time 6150ms: Process H completed a CPU burst; 76 bursts to go [Q O E D K F J]
time 6150ms: Process H switching out of CPU; will block on I/O until time 7112ms [Q O E D K F J]
time 6154ms: Process O started using the CPU for 13ms burst [Q E D K F J]
time 6167ms: Process O completed a CPU burst; 27 bursts to go [Q E D K F J]
time 6167ms: Process O switching out of CPU; will block on I/O until time 7499ms [Q E D K F J]
time 6171ms: Process E started using the CPU for 112ms burst [Q D K F J]
time 6228ms: Process A completed I/O; added to ready queue [Q D K F J A]
time 6268ms: Process B completed I/O; added to ready queue [Q D K F J A B]
time 6283ms: Process E completed a CPU burst; 48 bursts to go [Q D K F J A B]
time 6283ms: Process E switching out of CPU; will block on I/O until time 7395ms [Q D K F J A B]
time 6287ms: Process D started using the CPU for 4ms burst [Q K F J A B]
time 6291ms: Process D completed a CPU burst; 7 bursts to go [Q K F J A B]
time 6291ms: Process D switching out of CPU; will block on I/O until time 6773ms [Q K F J A B]
time 6295ms: Process K started using the CPU for 104ms burst [Q F J A B]
time 6399ms: Process K completed a CPU burst; 7 bursts to go [Q F J A B]
time 6399ms: Process K switching out of CPU; will block on I/O until time 7851ms [Q F J A B]
time 6403ms: Process F started using the CPU for 33ms burst [Q J A B]
time 6436ms: Process F completed a CPU burst; 27 bursts to go [Q J A B]
time 6436ms: Process F switching out of CPU; will block on I/O until time 6998ms [Q J A B]
time 6440ms: Process J started using the CPU for 23ms burst [Q A B]
time 6463ms: Process J completed a CPU burst; 3 bursts to go [Q A B]
time 6463ms: Process J switching out of CPU; will block on I/O until time 6625ms [Q A B]
time 6467ms: Process A started using the CPU for 68ms burst [Q B]
time 6535ms: Process A completed a CPU burst; 9 bursts to go [Q B]
time 6535ms: Process A switching out of CPU; will block on I/O until time 7177ms [Q B]
time 6539ms: Process B started using the CPU for 50ms burst [Q empty]
time 6589ms: Process B completed a CPU burst; 17 bursts to go [Q empty]
time 6589ms: Process B switching out of CPU; will block on I/O until time 7051ms [Q empty]
time 6624ms: Process L completed I/O; added to ready queue [Q L]
time 6626ms: Process L started using the CPU for 2ms burst [Q empty]
time 6625ms: Process J completed I/O; added to ready queue [Q J]
time 6628ms: Process L completed a CPU burst; 2 bursts to go [Q J]
time 6628ms: Process L switching out of CPU; will block on I/O until time 7000ms [Q J]
time 6632ms: Process J started using the CPU for 51ms burst [Q empty]
time 6683ms: Process J completed a CPU burst; 2 bursts to go [Q empty]
time 6683ms: Process J switching out of CPU; will block on I/O until time 7655ms [Q empty]
time 6700ms: Process I completed I/O; added to ready queue [Q I]
time 6702ms: Process I started using the CPU for 79ms burst [Q empty]
time 6714ms: Process P completed I/O; added to ready queue [Q P]
time 6773ms: Process D completed I/O; added to ready queue [Q P D]
time 6781ms: Process I completed a CPU burst; 71 bursts to go [Q P D]
time 6781ms: Process I switching out of CPU; will block on I/O until time 7943ms [Q P D]
time 6785ms: Process P started using the CPU for 155ms burst [Q D]
time 6940ms: Process P completed a CPU burst; 12 bursts to go [Q D]
time 6940ms: Process P switching out of CPU; will block on I/O until time 8122ms [Q D]
time 6944ms: Process D started using the CPU for 149ms burst [Q empty]
time 6998ms: Process F completed I/O; added to ready queue [Q F]
time 7000ms: Process G completed I/O; added to ready queue [Q F G]
time 7000ms: Process L completed I/O; added to ready queue [Q F G L]
time 7051ms: Process B completed I/O; added to ready queue [Q F G L B]
time 7093ms: Process D completed a CPU burst; 6 bursts to go [Q F G L B]
time 7093ms: Process D switching out of CPU; will block on I/O until time 7905ms [Q F G L B]
time 7097ms: Process F started using the CPU for 76ms burst [Q G L B]
time 7111ms: Process M completed I/O; added to ready queue [Q G L B M]
time 7112ms: Process H completed I/O; added to ready queue [Q G L B M H]
time 7173ms: Process F completed a CPU burst; 26 bursts to go [Q G L B M H]
time 7173ms: Process F switching out of CPU; will block on I/O until time 7555ms [Q G L B M H]
time 7177ms: Process G started using the CPU for 15ms burst [Q L B M H]
time 7177ms: Process A completed I/O; added to ready queue [Q L B M H A]
time 7192ms: Process G completed a CPU burst; 74 bursts to go [Q L B M H A]
time 7192ms: Process G switching out of CPU; will block on I/O until time 8134ms [Q L B M H A]
time 7196ms: Process L started using the CPU for 164ms burst [Q B M H A]
time 7360ms: Process L completed a CPU burst; 1 bursts to go [Q B M H A]
time 7360ms: Process L switching out of CPU; will block on I/O until time 7862ms [Q B M H A]
time 7364ms: Process B started using the CPU for 82ms burst [Q M H A]
time 7395ms: Process E completed I/O; added to ready queue [Q M H A E]
time 7446ms: Process B completed a CPU burst; 16 bursts to go [Q M H A E]
time 7446ms: Process B switching out of CPU; will block on I/O until time 7608ms [Q M H A E]
time 7450ms: Process M started using the CPU for 66ms burst [Q H A E]
time 7499ms: Process O completed I/O; added to ready queue [Q H A E O]
time 7516ms: Process M completed a CPU burst; 43 bursts to go [Q H A E O]
time 7516ms: Process M switching out of CPU; will block on I/O until time 9328ms [Q H A E O]
time 7520ms: Process H started using the CPU for 51ms burst [Q A E O]
time 7519ms: Process N completed I/O; added to ready queue [Q A E O N]
time 7555ms: Process F completed I/O; added to ready queue [Q A E O N F]
time 7571ms: Process H completed a CPU burst; 75 bursts to go [Q A E O N F]
time 7571ms: Process H switching out of CPU; will block on I/O until time 7803ms [Q A E O N F]
time 7575ms: Process A started using the CPU for 113ms burst [Q E O N F]
time 7608ms: Process B completed I/O; added to ready queue [Q E O N F B]
time 7655ms: Process J completed I/O; added to ready queue [Q E O N F B J]
time 7688ms: Process A completed a CPU burst; 8 bursts to go [Q E O N F B J]
time 7688ms: Process A switching out of CPU; will block on I/O until time 7850ms [Q E O N F B J]
time 7692ms: Process E started using the CPU for 12ms burst [Q O N F B J]
time 7704ms: Process E completed a CPU burst; 47 bursts to go [Q O N F B J]
time 7704ms: Process E switching out of CPU; will block on I/O until time 8156ms [Q O N F B J]
time 7708ms: Process O started using the CPU for 130ms burst [Q N F B J]
time 7803ms: Process H completed I/O; added to ready queue [Q N F B J H]
time 7838ms: Process O completed a CPU burst; 26 bursts to go [Q N F B J H]
time 7838ms: Process O switching out of CPU; will block on I/O until time 8550ms [Q N F B J H]
time 7842ms: Process N started using the CPU for 27ms burst [Q F B J H]
time 7850ms: Process A completed I/O; added to ready queue [Q F B J H A]
time 7851ms: Process K completed I/O; added to ready queue [Q F B J H A K]
time 7862ms: Process L completed I/O; added to ready queue [Q F B J H A K L]
time 7869ms: Process N completed a CPU burst; 26 bursts to go [Q F B J H A K L]
time 7869ms: Process N switching out of CPU; will block on I/O until time 8141ms [Q F B J H A K L]
time 7873ms: Process F started using the CPU for 107ms burst [Q B J H A K L]
time 7905ms: Process D completed I/O; added to ready queue [Q B J H A K L D]
time 7943ms: Process I completed I/O; added to ready queue [Q B J H A K L D I]
time 7980ms: Process F completed a CPU burst; 25 bursts to go [Q B J H A K L D I]
time 7980ms: Process F switching out of CPU; will block on I/O until time 8162ms [Q B J H A K L D I]
time 7984ms: Process B started using the CPU for 7ms burst [Q J H A K L D I]
time 7991ms: Process B completed a CPU burst; 15 bursts to go [Q J H A K L D I]
time 7991ms: Process B switching out of CPU; will block on I/O until time 8293ms [Q J H A K L D I]
time 7995ms: Process J started using the CPU for 216ms burst [Q H A K L D I]
time 8122ms: Process P completed I/O; added to ready queue [Q H A K L D I P]
time 8134ms: Process G completed I/O; added to ready queue [Q H A K L D I P G]
time 8141ms: Process N completed I/O; added to ready queue [Q H A K L D I P G N]
time 8156ms: Process E completed I/O; added to ready queue [Q H A K L D I P G N E]
time 8162ms: Process F completed I/O; added to ready queue [Q H A K L D I P G N E F]
time 8211ms: Process J completed a CPU burst; 1 bursts to go [Q H A K L D I P G N E F]
time 8211ms: Process J switching out of CPU; will block on I/O until time 8293ms [Q H A K L D I P G N E F]
time 8215ms: Process H started using the CPU for 87ms burst [Q A K L D I P G N E F]
time 8293ms: Process B completed I/O; added to ready queue [Q A K L D I P G N E F B]
time 8293ms: Process J completed I/O; added to ready queue [Q A K L D I P G N E F B J]
time 8302ms: Process H completed a CPU burst; 74 bursts to go [Q A K L D I P G N E F B J]
time 8302ms: Process H switching out of CPU; will block on I/O until time 8874ms [Q A K L D I P G N E F B J]
time 8306ms: Process A started using the CPU for 11ms burst [Q K L D I P G N E F B J]
time 8317ms: Process A completed a CPU burst; 7 bursts to go [Q K L D I P G N E F B J]
time 8317ms: Process A switching out of CPU; will block on I/O until time 9939ms [Q K L D I P G N E F B J]
time 8321ms: Process K started using the CPU for 86ms burst [Q L D I P G N E F B J]
time 8407ms: Process K completed a CPU burst; 6 bursts to go [Q L D I P G N E F B J]
time 8407ms: Process K switching out of CPU; will block on I/O until time 8689ms [Q L D I P G N E F B J]
time 8411ms: Process L started using the CPU for 111ms burst [Q D I P G N E F B J]
time 8522ms: Process L terminated [Q D I P G N E F B J]
time 8526ms: Process D started using the CPU for 52ms burst [Q I P G N E F B J]
time 8550ms: Process O completed I/O; added to ready queue [Q I P G N E F B J O]
time 8578ms: Process D completed a CPU burst; 5 bursts to go [Q I P G N E F B J O]
time 8578ms: Process D switching out of CPU; will block on I/O until time 8610ms [Q I P G N E F B J O]
time 8582ms: Process I started using the CPU for 84ms burst [Q P G N E F B J O]
time 8610ms: Process D completed I/O; added to ready queue [Q P G N E F B J O D]
time 8666ms: Process I completed a CPU burst; 70 bursts to go [Q P G N E F B J O D]
time 8666ms: Process I switching out of CPU; will block on I/O until time 9178ms [Q P G N E F B J O D]
time 8670ms: Process P started using the CPU for 4ms burst [Q G N E F B J O D]
time 8674ms: Process P completed a CPU burst; 11 bursts to go [Q G N E F B J O D]
time 8674ms: Process P switching out of CPU; will block on I/O until time 10466ms [Q G N E F B J O D]
time 8678ms: Process G started using the CPU for 112ms burst [Q N E F B J O D]
time 8689ms: Process K completed I/O; added to ready queue [Q N E F B J O D K]
time 8790ms: Process G completed a CPU burst; 73 bursts to go [Q N E F B J O D K]
time 8790ms: Process G switching out of CPU; will block on I/O until time 9222ms [Q N E F B J O D K]
time 8794ms: Process N started using the CPU for 57ms burst [Q E F B J O D K]
time 8851ms: Process N completed a CPU burst; 25 bursts to go [Q E F B J O D K]
time 8851ms: Process N switching out of CPU; will block on I/O until time 8953ms [Q E F B J O D K]
time 8855ms: Process E started using the CPU for 9ms burst [Q F B J O D K]
time 8864ms: Process E completed a CPU burst; 46 bursts to go [Q F B J O D K]
time 8864ms: Process E switching out of CPU; will block on I/O until time 9536ms [Q F B J O D K]
time 8868ms: Process F started using the CPU for 89ms burst [Q B J O D K]
time 8874ms: Process H completed I/O; added to ready queue [Q B J O D K H]
time 8953ms: Process N completed I/O; added to ready queue [Q B J O D K H N]
time 8957ms: Process F completed a CPU burst; 24 bursts to go [Q B J O D K H N]
time 8957ms: Process F switching out of CPU; will block on I/O until time 9789ms [Q B J O D K H N]
time 8961ms: Process B started using the CPU for 52ms burst [Q J O D K H N]
time 9013ms: Process B completed a CPU burst; 14 bursts to go [Q J O D K H N]
time 9013ms: Process B switching out of CPU; will block on I/O until time 9135ms [Q J O D K H N]
time 9017ms: Process J started using the CPU for 7ms burst [Q O D K H N]
time 9024ms: Process J terminated [Q O D K H N]
time 9028ms: Process O started using the CPU for 68ms burst [Q D K H N]
time 9096ms: Process O completed a CPU burst; 25 bursts to go [Q D K H N]
time 9096ms: Process O switching out of CPU; will block on I/O until time 10268ms [Q D K H N]
time 9100ms: Process D started using the CPU for 23ms burst [Q K H N]
time 9123ms: Process D completed a CPU burst; 4 bursts to go [Q K H N]
time 9123ms: Process D switching out of CPU; will block on I/O until time 11065ms [Q K H N]
time 9127ms: Process K started using the CPU for 50ms burst [Q H N]
time 9135ms: Process B completed I/O; added to ready queue [Q H N B]
time 9177ms: Process K completed a CPU burst; 5 bursts to go [Q H N B]
time 9177ms: Process K switching out of CPU; will block on I/O until time 9679ms [Q H N B]
time 9178ms: Process I completed I/O; added to ready queue [Q H N B I]
time 9181ms: Process H started using the CPU for 156ms burst [Q N B I]
time 9222ms: Process G completed I/O; added to ready queue [Q N B I G]
time 9328ms: Process M completed I/O; added to ready queue [Q N B I G M]
time 9337ms: Process H completed a CPU burst; 73 bursts to go [Q N B I G M]
time 9337ms: Process H switching out of CPU; will block on I/O until time 9899ms [Q N B I G M]
time 9341ms: Process N started using the CPU for 84ms burst [Q B I G M]
time 9425ms: Process N completed a CPU burst; 24 bursts to go [Q B I G M]
time 9425ms: Process N switching out of CPU; will block on I/O until time 9447ms [Q B I G M]
time 9429ms: Process B started using the CPU for 228ms burst [Q I G M]
time 9447ms: Process N completed I/O; added to ready queue [Q I G M N]
time 9536ms: Process E completed I/O; added to ready queue [Q I G M N E]
time 9657ms: Process B completed a CPU burst; 13 bursts to go [Q I G M N E]
time 9657ms: Process B switching out of CPU; will block on I/O until time 10429ms [Q I G M N E]
time 9661ms: Process I started using the CPU for 27ms burst [Q G M N E]
time 9679ms: Process K completed I/O; added to ready queue [Q G M N E K]
time 9688ms: Process I completed a CPU burst; 69 bursts to go [Q G M N E K]
time 9688ms: Process I switching out of CPU; will block on I/O until time 11590ms [Q G M N E K]
time 9692ms: Process G started using the CPU for 30ms burst [Q M N E K]
time 9722ms: Process G completed a CPU burst; 72 bursts to go [Q M N E K]
time 9722ms: Process G switching out of CPU; will block on I/O until time 10194ms [Q M N E K]
time 9726ms: Process M started using the CPU for 103ms burst [Q N E K]
time 9789ms: Process F completed I/O; added to ready queue [Q N E K F]
time 9829ms: Process M completed a CPU burst; 42 bursts to go [Q N E K F]
time 9829ms: Process M switching out of CPU; will block on I/O until time 10231ms [Q N E K F]
time 9833ms: Process N started using the CPU for 131ms burst [Q E K F]
time 9899ms: Process H completed I/O; added to ready queue [Q E K F H]
time 9939ms: Process A completed I/O; added to ready queue [Q E K F H A]
time 9964ms: Process N completed a CPU burst; 23 bursts to go [Q E K F H A]
time 9964ms: Process N switching out of CPU; will block on I/O until time 10196ms [Q E K F H A]
time 9968ms: Process E started using the CPU for 62ms burst [Q K F H A]
time 10030ms: Process E completed a CPU burst; 45 bursts to go [Q K F H A]
time 10030ms: Process E switching out of CPU; will block on I/O until time 10632ms [Q K F H A]
time 10034ms: Process K started using the CPU for 4ms burst [Q F H A]
time 10038ms: Process K completed a CPU burst; 4 bursts to go [Q F H A]
time 10038ms: Process K switching out of CPU; will block on I/O until time 10640ms [Q F H A]
time 10042ms: Process F started using the CPU for 102ms burst [Q H A]
time 10144ms: Process F completed a CPU burst; 23 bursts to go [Q H A]
time 10144ms: Process F switching out of CPU; will block on I/O until time 11496ms [Q H A]
time 10148ms: Process H started using the CPU for 184ms burst [Q A]
time 10194ms: Process G completed I/O; added to ready queue [Q A G]
time 10196ms: Process N completed I/O; added to ready queue [Q A G N]
time 10231ms: Process M completed I/O; added to ready queue [Q A G N M]
time 10268ms: Process O completed I/O; added to ready queue [Q A G N M O]
time 10332ms: Process H completed a CPU burst; 72 bursts to go [Q A G N M O]
time 10332ms: Process H switching out of CPU; will block on I/O until time 10594ms [Q A G N M O]
time 10336ms: Process A started using the CPU for 24ms burst [Q G N M O]
time 10360ms: Process A completed a CPU burst; 6 bursts to go [Q G N M O]
time 10360ms: Process A switching out of CPU; will block on I/O until time 11532ms [Q G N M O]
time 10364ms: Process G started using the CPU for 50ms burst [Q N M O]
time 10414ms: Process G completed a CPU burst; 71 bursts to go [Q N M O]
time 10414ms: Process G switching out of CPU; will block on I/O until time 12616ms [Q N M O]
time 10418ms: Process N started using the CPU for 222ms burst [Q M O]
time 10429ms: Process B completed I/O; added to ready queue [Q M O B]
time 10466ms: Process P completed I/O; added to ready queue [Q M O B P]
time 10594ms: Process H completed I/O; added to ready queue [Q M O B P H]
time 10632ms: Process E completed I/O; added to ready queue [Q M O B P H E]
time 10640ms: Process K completed I/O; added to ready queue [Q M O B P H E K]
time 10640ms: Process N completed a CPU burst; 22 bursts to go [Q M O B P H E K]
time 10640ms: Process N switching out of CPU; will block on I/O until time 10692ms [Q M O B P H E K]
time 10644ms: Process M started using the CPU for 171ms burst [Q O B P H E K]
time 10692ms: Process N completed I/O; added to ready queue [Q O B P H E K N]
time 10815ms: Process M completed a CPU burst; 41 bursts to go [Q O B P H E K N]
time 10815ms: Process M switching out of CPU; will block on I/O until time 11027ms [Q O B P H E K N]
time 10819ms: Process O started using the CPU for 136ms burst [Q B P H E K N]
time 10955ms: Process O completed a CPU burst; 24 bursts to go [Q B P H E K N]
time 10955ms: Process O switching out of CPU; will block on I/O until time 12007ms [Q B P H E K N]
time 10959ms: Process B started using the CPU for 138ms burst [Q P H E K N]
time 11027ms: Process M completed I/O; added to ready queue [Q P H E K N M]
time 11065ms: Process D completed I/O; added to ready queue [Q P H E K N M D]
time 11097ms: Process B completed a CPU burst; 12 bursts to go [Q P H E K N M D]
time 11097ms: Process B switching out of CPU; will block on I/O until time 11919ms [Q P H E K N M D]
time 11101ms: Process P started using the CPU for 105ms burst [Q H E K N M D]
time 11206ms: Process P completed a CPU burst; 10 bursts to go [Q H E K N M D]
time 11206ms: Process P switching out of CPU; will block on I/O until time 11798ms [Q H E K N M D]
time 11210ms: Process H started using the CPU for 2ms burst [Q E K N M D]
time 11212ms: Process H completed a CPU burst; 71 bursts to go [Q E K N M D]
time 11212ms: Process H switching out of CPU; will block on I/O until time 11354ms [Q E K N M D]
time 11216ms: Process E started using the CPU for 213ms burst [Q K N M D]
time 11354ms: Process H completed I/O; added to ready queue [Q K N M D H]
time 11429ms: Process E completed a CPU burst; 44 bursts to go [Q K N M D H]
time 11429ms: Process E switching out of CPU; will block on I/O until time 13361ms [Q K N M D H]
time 11433ms: Process K started using the CPU for 21ms burst [Q N M D H]
time 11454ms: Process K completed a CPU burst; 3 bursts to go [Q N M D H]
time 11454ms: Process K switching out of CPU; will block on I/O until time 12106ms [Q N M D H]
time 11458ms: Process N started using the CPU for 148ms burst [Q M D H]
time 11496ms: Process F completed I/O; added to ready queue [Q M D H F]
time 11532ms: Process A completed I/O; added to ready queue [Q M D H F A]
time 11590ms: Process I completed I/O; added to ready queue [Q M D H F A I]
time 11606ms: Process N completed a CPU burst; 21 bursts to go [Q M D H F A I]
time 11606ms: Process N switching out of CPU; will block on I/O until time 12988ms [Q M D H F A I]
time 11610ms: Process M started using the CPU for 200ms burst [Q D H F A I]
time 11798ms: Process P completed I/O; added to ready queue [Q D H F A I P]
time 11810ms: Process M completed a CPU burst; 40 bursts to go [Q D H F A I P]
time 11810ms: Process M switching out of CPU; will block on I/O until time 13122ms [Q D H F A I P]
time 11814ms: Process D started using the CPU for 76ms burst [Q H F A I P]
time 11890ms: Process D completed a CPU burst; 3 bursts to go [Q H F A I P]
time 11890ms: Process D switching out of CPU; will block on I/O until time 12622ms [Q H F A I P]
time 11894ms: Process H started using the CPU for 29ms burst [Q F A I P]
time 11919ms: Process B completed I/O; added to ready queue [Q F A I P B]
time 11923ms: Process H completed a CPU burst; 70 bursts to go [Q F A I P B]
time 11923ms: Process H switching out of CPU; will block on I/O until time 14145ms [Q F A I P B]
time 11927ms: Process F started using the CPU for 147ms burst [Q A I P B]
time 12007ms: Process O completed I/O; added to ready queue [Q A I P B O]
time 12074ms: Process F completed a CPU burst; 22 bursts to go [Q A I P B O]
time 12074ms: Process F switching out of CPU; will block on I/O until time 12126ms [Q A I P B O]
time 12078ms: Process A started using the CPU for 76ms burst [Q I P B O]
time 12106ms: Process K completed I/O; added to ready queue [Q I P B O K]
time 12126ms: Process F completed I/O; added to ready queue [Q I P B O K F]
time 12154ms: Process A completed a CPU burst; 5 bursts to go [Q I P B O K F]
time 12154ms: Process A switching out of CPU; will block on I/O until time 12436ms [Q I P B O K F]
time 12158ms: Process I started using the CPU for 70ms burst [Q P B O K F]
time 12228ms: Process I completed a CPU burst; 68 bursts to go [Q P B O K F]
time 12228ms: Process I switching out of CPU; will block on I/O until time 13770ms [Q P B O K F]
time 12232ms: Process P started using the CPU for 16ms burst [Q B O K F]
time 12248ms: Process P completed a CPU burst; 9 bursts to go [Q B O K F]
time 12248ms: Process P switching out of CPU; will block on I/O until time 12900ms [Q B O K F]
time 12252ms: Process B started using the CPU for 67ms burst [Q O K F]
time 12319ms: Process B completed a CPU burst; 11 bursts to go [Q O K F]
time 12319ms: Process B switching out of CPU; will block on I/O until time 12391ms [Q O K F]
time 12323ms: Process O started using the CPU for 69ms burst [Q K F]
time 12391ms: Process B completed I/O; added to ready queue [Q K F B]
time 12392ms: Process O completed a CPU burst; 23 bursts to go [Q K F B]
time 12392ms: Process O switching out of CPU; will block on I/O until time 13144ms [Q K F B]
time 12396ms: Process K started using the CPU for 120ms burst [Q F B]
time 12436ms: Process A completed I/O; added to ready queue [Q F B A]
time 12516ms: Process K completed a CPU burst; 2 bursts to go [Q F B A]
time 12516ms: Process K switching out of CPU; will block on I/O until time 13208ms [Q F B A]
time 12520ms: Process F started using the CPU for 97ms burst [Q B A]
time 12616ms: Process G completed I/O; added to ready queue [Q B A G]
time 12617ms: Process F completed a CPU burst; 21 bursts to go [Q B A G]
time 12617ms: Process F switching out of CPU; will block on I/O until time 12659ms [Q B A G]
time 12621ms: Process B started using the CPU for 120ms burst [Q A G]
time 12622ms: Process D completed I/O; added to ready queue [Q A G D]
time 12659ms: Process F completed I/O; added to ready queue [Q A G D F]
time 12741ms: Process B completed a CPU burst; 10 bursts to go [Q A G D F]
time 12741ms: Process B switching out of CPU; will block on I/O until time 12873ms [Q A G D F]
time 12745ms: Process A started using the CPU for 122ms burst [Q G D F]
time 12867ms: Process A completed a CPU burst; 4 bursts to go [Q G D F]
time 12867ms: Process A switching out of CPU; will block on I/O until time 13199ms [Q G D F]
time 12871ms: Process G started using the CPU for 5ms burst [Q D F]
time 12873ms: Process B completed I/O; added to ready queue [Q D F B]
time 12876ms: Process G completed a CPU burst; 70 bursts to go [Q D F B]
time 12876ms: Process G switching out of CPU; will block on I/O until time 14858ms [Q D F B]
time 12880ms: Process D started using the CPU for 50ms burst [Q F B]
time 12900ms: Process P completed I/O; added to ready queue [Q F B P]
time 12930ms: Process D completed a CPU burst; 2 bursts to go [Q F B P]
time 12930ms: Process D switching out of CPU; will block on I/O until time 13052ms [Q F B P]
time 12934ms: Process F started using the CPU for 157ms burst [Q B P]
time 12988ms: Process N completed I/O; added to ready queue [Q B P N]
time 13052ms: Process D completed I/O; added to ready queue [Q B P N D]
time 13091ms: Process F completed a CPU burst; 20 bursts to go [Q B P N D]
time 13091ms: Process F switching out of CPU; will block on I/O until time 13193ms [Q B P N D]
time 13095ms: Process B started using the CPU for 49ms burst [Q P N D]
time 13122ms: Process M completed I/O; added to ready queue [Q P N D M]
time 13144ms: Process O completed I/O; added to ready queue [Q P N D M O]
time 13144ms: Process B completed a CPU burst; 9 bursts to go [Q P N D M O]
time 13144ms: Process B switching out of CPU; will block on I/O until time 13566ms [Q P N D M O]
time 13148ms: Process P started using the CPU for 219ms burst [Q N D M O]
time 13193ms: Process F completed I/O; added to ready queue [Q N D M O F]
time 13199ms: Process A completed I/O; added to ready queue [Q N D M O F A]
time 13208ms: Process K completed I/O; added to ready queue [Q N D M O F A K]
time 13361ms: Process E completed I/O; added to ready queue [Q N D M O F A K E]
time 13367ms: Process P completed a CPU burst; 8 bursts to go [Q N D M O F A K E]
time 13367ms: Process P switching out of CPU; will block on I/O until time 15419ms [Q N D M O F A K E]
time 13371ms: Process N started using the CPU for 32ms burst [Q D M O F A K E]
time 13403ms: Process N completed a CPU burst; 20 bursts to go [Q D M O F A K E]
time 13403ms: Process N switching out of CPU; will block on I/O until time 14985ms [Q D M O F A K E]
time 13407ms: Process D started using the CPU for 24ms burst [Q M O F A K E]
time 13431ms: Process D completed a CPU burst; 1 bursts to go [Q M O F A K E]
time 13431ms: Process D switching out of CPU; will block on I/O until time 13683ms [Q M O F A K E]
time 13435ms: Process M started using the CPU for 117ms burst [Q O F A K E]
time 13552ms: Process M completed a CPU burst; 39 bursts to go [Q O F A K E]
time 13552ms: Process M switching out of CPU; will block on I/O until time 14894ms [Q O F A K E]
time 13556ms: Process O started using the CPU for 6ms burst [Q F A K E]
time 13562ms: Process O completed a CPU burst; 22 bursts to go [Q F A K E]
time 13562ms: Process O switching out of CPU; will block on I/O until time 15204ms [Q F A K E]
time 13566ms: Process F started using the CPU for 24ms burst [Q A K E]
time 13566ms: Process B completed I/O; added to ready queue [Q A K E B]
time 13590ms: Process F completed a CPU burst; 19 bursts to go [Q A K E B]
time 13590ms: Process F switching out of CPU; will block on I/O until time 14562ms [Q A K E B]
time 13594ms: Process A started using the CPU for 9ms burst [Q K E B]
time 13603ms: Process A completed a CPU burst; 3 bursts to go [Q K E B]
time 13603ms: Process A switching out of CPU; will block on I/O until time 14285ms [Q K E B]
time 13607ms: Process K started using the CPU for 199ms burst [Q E B]
time 13683ms: Process D completed I/O; added to ready queue [Q E B D]
time 13770ms: Process I completed I/O; added to ready queue [Q E B D I]
time 13806ms: Process K completed a CPU burst; 1 bursts to go [Q E B D I]
time 13806ms: Process K switching out of CPU; will block on I/O until time 14458ms [Q E B D I]
time 13810ms: Process E started using the CPU for 54ms burst [Q B D I]
time 13864ms: Process E completed a CPU burst; 43 bursts to go [Q B D I]
time 13864ms: Process E switching out of CPU; will block on I/O until time 14816ms [Q B D I]
time 13868ms: Process B started using the CPU for 134ms burst [Q D I]
time 14002ms: Process B completed a CPU burst; 8 bursts to go [Q D I]
time 14002ms: Process B switching out of CPU; will block on I/O until time 14324ms [Q D I]
time 14006ms: Process D started using the CPU for 1ms burst [Q I]
time 14007ms: Process D terminated [Q I]
time 14011ms: Process I started using the CPU for 107ms burst [Q empty]
time 14118ms: Process I completed a CPU burst; 67 bursts to go [Q empty]
time 14118ms: Process I switching out of CPU; will block on I/O until time 14590ms [Q empty]
time 14145ms: Process H completed I/O; added to ready queue [Q H]
time 14147ms: Process H started using the CPU for 76ms burst [Q empty]
time 14223ms: Process H completed a CPU burst; 69 bursts to go [Q empty]
time 14223ms: Process H switching out of CPU; will block on I/O until time 16345ms [Q empty]
time 14285ms: Process A completed I/O; added to ready queue [Q A]
time 14287ms: Process A started using the CPU for 62ms burst [Q empty]
time 14324ms: Process B completed I/O; added to ready queue [Q B]
time 14349ms: Process A completed a CPU burst; 2 bursts to go [Q B]
time 14349ms: Process A switching out of CPU; will block on I/O until time 15121ms [Q B]
time 14353ms: Process B started using the CPU for 144ms burst [Q empty]
time 14458ms: Process K completed I/O; added to ready queue [Q K]
time 14497ms: Process B completed a CPU burst; 7 bursts to go [Q K]
time 14497ms: Process B switching out of CPU; will block on I/O until time 15289ms [Q K]
time 14501ms: Process K started using the CPU for 47ms burst [Q empty]
time 14548ms: Process K terminated [Q empty]
time 14562ms: Process F completed I/O; added to ready queue [Q F]
time 14564ms: Process F started using the CPU for 31ms burst [Q empty]
time 14590ms: Process I completed I/O; added to ready queue [Q I]
time 14595ms: Process F completed a CPU burst; 18 bursts to go [Q I]
time 14595ms: Process F switching out of CPU; will block on I/O until time 14807ms [Q I]
time 14599ms: Process I started using the CPU for 21ms burst [Q empty]
time 14620ms: Process I completed a CPU burst; 66 bursts to go [Q empty]
time 14620ms: Process I switching out of CPU; will block on I/O until time 14712ms [Q empty]
time 14712ms: Process I completed I/O; added to ready queue [Q I]
time 14714ms: Process I started using the CPU for 179ms burst [Q empty]
time 14807ms: Process F completed I/O; added to ready queue [Q F]
time 14816ms: Process E completed I/O; added to ready queue [Q F E]
time 14858ms: Process G completed I/O; added to ready queue [Q F E G]
time 14893ms: Process I completed a CPU burst; 65 bursts to go [Q F E G]
time 14893ms: Process I switching out of CPU; will block on I/O until time 15895ms [Q F E G]
time 14894ms: Process M completed I/O; added to ready queue [Q F E G M]
time 14897ms: Process F started using the CPU for 24ms burst [Q E G M]
time 14921ms: Process F completed a CPU burst; 17 bursts to go [Q E G M]
time 14921ms: Process F switching out of CPU; will block on I/O until time 15513ms [Q E G M]
time 14925ms: Process E started using the CPU for 126ms burst [Q G M]
time 14985ms: Process N completed I/O; added to ready queue [Q G M N]
time 15051ms: Process E completed a CPU burst; 42 bursts to go [Q G M N]
time 15051ms: Process E switching out of CPU; will block on I/O until time 17033ms [Q G M N]
time 15055ms: Process G started using the CPU for 122ms burst [Q M N]
time 15121ms: Process A completed I/O; added to ready queue [Q M N A]
time 15177ms: Process G completed a CPU burst; 69 bursts to go [Q M N A]
time 15177ms: Process G switching out of CPU; will block on I/O until time 15529ms [Q M N A]
time 15181ms: Process M started using the CPU for 6ms burst [Q N A]
time 15187ms: Process M completed a CPU burst; 38 bursts to go [Q N A]
time 15187ms: Process M switching out of CPU; will block on I/O until time 15519ms [Q N A]
time 15191ms: Process N started using the CPU for 97ms burst [Q A]
time 15204ms: Process O completed I/O; added to ready queue [Q A O]
time 15288ms: Process N completed a CPU burst; 19 bursts to go [Q A O]
time 15288ms: Process N switching out of CPU; will block on I/O until time 16200ms [Q A O]
time 15289ms: Process B completed I/O; added to ready queue [Q A O B]
time 15292ms: Process A started using the CPU for 200ms burst [Q O B]
time 15419ms: Process P completed I/O; added to ready queue [Q O B P]
time 15492ms: Process A completed a CPU burst; 1 bursts to go [Q O B P]
time 15492ms: Process A switching out of CPU; will block on I/O until time 15604ms [Q O B P]
time 15496ms: Process O started using the CPU for 187ms burst [Q B P]
time 15513ms: Process F completed I/O; added to ready queue [Q B P F]
time 15519ms: Process M completed I/O; added to ready queue [Q B P F M]
time 15529ms: Process G completed I/O; added to ready queue [Q B P F M G]
time 15604ms: Process A completed I/O; added to ready queue [Q B P F M G A]
time 15683ms: Process O completed a CPU burst; 21 bursts to go [Q B P F M G A]
time 15683ms: Process O switching out of CPU; will block on I/O until time 17355ms [Q B P F M G A]
time 15687ms: Process B started using the CPU for 183ms burst [Q P F M G A]
time 15870ms: Process B completed a CPU burst; 6 bursts to go [Q P F M G A]
time 15870ms: Process B switching out of CPU; will block on I/O until time 15932ms [Q P F M G A]
time 15874ms: Process P started using the CPU for 70ms burst [Q F M G A]
time 15895ms: Process I completed I/O; added to ready queue [Q F M G A I]
time 15932ms: Process B completed I/O; added to ready queue [Q F M G A I B]
time 15944ms: Process P completed a CPU burst; 7 bursts to go [Q F M G A I B]
time 15944ms: Process P switching out of CPU; will block on I/O until time 17216ms [Q F M G A I B]
time 15948ms: Process F started using the CPU for 135ms burst [Q M G A I B]
time 16083ms: Process F completed a CPU burst; 16 bursts to go [Q M G A I B]
time 16083ms: Process F switching out of CPU; will block on I/O until time 16705ms [Q M G A I B]
time 16087ms: Process M started using the CPU for 141ms burst [Q G A I B]
time 16200ms: Process N completed I/O; added to ready queue [Q G A I B N]
time 16228ms: Process M completed a CPU burst; 37 bursts to go [Q G A I B N]
time 16228ms: Process M switching out of CPU; will block on I/O until time 16450ms [Q G A I B N]
time 16232ms: Process G started using the CPU for 31ms burst [Q A I B N]
time 16263ms: Process G completed a CPU burst; 68 bursts to go [Q A I B N]
time 16263ms: Process G switching out of CPU; will block on I/O until time 16335ms [Q A I B N]
time 16267ms: Process A started using the CPU for 197ms burst [Q I B N]
time 16335ms: Process G completed I/O; added to ready queue [Q I B N G]
time 16345ms: Process H completed I/O; added to ready queue [Q I B N G H]
time 16450ms: Process M completed I/O; added to ready queue [Q I B N G H M]
time 16464ms: Process A terminated [Q I B N G H M]
time 16468ms: Process I started using the CPU for 65ms burst [Q B N G H M]
time 16533ms: Process I completed a CPU burst; 64 bursts to go [Q B N G H M]
time 16533ms: Process I switching out of CPU; will block on I/O until time 16855ms [Q B N G H M]
time 16537ms: Process B started using the CPU for 219ms burst [Q N G H M]
time 16705ms: Process F completed I/O; added to ready queue [Q N G H M F]
time 16756ms: Process B completed a CPU burst; 5 bursts to go [Q N G H M F]
time 16756ms: Process B switching out of CPU; will block on I/O until time 16988ms [Q N G H M F]
time 16760ms: Process N started using the CPU for 39ms burst [Q G H M F]
time 16799ms: Process N completed a CPU burst; 18 bursts to go [Q G H M F]
time 16799ms: Process N switching out of CPU; will block on I/O until time 16811ms [Q G H M F]
time 16803ms: Process G started using the CPU for 61ms burst [Q H M F]
time 16811ms: Process N completed I/O; added to ready queue [Q H M F N]
time 16855ms: Process I completed I/O; added to ready queue [Q H M F N I]
time 16864ms: Process G completed a CPU burst; 67 bursts to go [Q H M F N I]
time 16864ms: Process G switching out of CPU; will block on I/O until time 17606ms [Q H M F N I]
time 16868ms: Process H started using the CPU for 143ms burst [Q M F N I]
time 16988ms: Process B completed I/O; added to ready queue [Q M F N I B]
time 17011ms: Process H completed a CPU burst; 68 bursts to go [Q M F N I B]
time 17011ms: Process H switching out of CPU; will block on I/O until time 18853ms [Q M F N I B]
time 17015ms: Process M started using the CPU for 13ms burst [Q F N I B]
time 17028ms: Process M completed a CPU burst; 36 bursts to go [Q F N I B]
time 17028ms: Process M switching out of CPU; will block on I/O until time 17150ms [Q F N I B]
time 17032ms: Process F started using the CPU for 87ms burst [Q N I B]
time 17033ms: Process E completed I/O; added to ready queue [Q N I B E]
time 17119ms: Process F completed a CPU burst; 15 bursts to go [Q N I B E]
time 17119ms: Process F switching out of CPU; will block on I/O until time 18161ms [Q N I B E]
time 17123ms: Process N started using the CPU for 137ms burst [Q I B E]
time 17150ms: Process M completed I/O; added to ready queue [Q I B E M]
time 17216ms: Process P completed I/O; added to ready queue [Q I B E M P]
time 17260ms: Process N completed a CPU burst; 17 bursts to go [Q I B E M P]
time 17260ms: Process N switching out of CPU; will block on I/O until time 17452ms [Q I B E M P]
time 17264ms: Process I started using the CPU for 58ms burst [Q B E M P]
time 17322ms: Process I completed a CPU burst; 63 bursts to go [Q B E M P]
time 17322ms: Process I switching out of CPU; will block on I/O until time 19064ms [Q B E M P]
time 17326ms: Process B started using the CPU for 64ms burst [Q E M P]
time 17355ms: Process O completed I/O; added to ready queue [Q E M P O]
time 17390ms: Process B completed a CPU burst; 4 bursts to go [Q E M P O]
time 17390ms: Process B switching out of CPU; will block on I/O until time 18192ms [Q E M P O]
time 17394ms: Process E started using the CPU for 168ms burst [Q M P O]
time 17452ms: Process N completed I/O; added to ready queue [Q M P O N]
time 17562ms: Process E completed a CPU burst; 41 bursts to go [Q M P O N]
time 17562ms: Process E switching out of CPU; will block on I/O until time 18064ms [Q M P O N]
time 17566ms: Process M started using the CPU for 103ms burst [Q P O N]
time 17606ms: Process G completed I/O; added to ready queue [Q P O N G]
time 17669ms: Process M completed a CPU burst; 35 bursts to go [Q P O N G]
time 17669ms: Process M switching out of CPU; will block on I/O until time 17811ms [Q P O N G]
time 17673ms: Process P started using the CPU for 55ms burst [Q O N G]
time 17728ms: Process P completed a CPU burst; 6 bursts to go [Q O N G]
time 17728ms: Process P switching out of CPU; will block on I/O until time 20180ms [Q O N G]
time 17732ms: Process O started using the CPU for 89ms burst [Q N G]
time 17811ms: Process M completed I/O; added to ready queue [Q N G M]
time 17821ms: Process O completed a CPU burst; 20 bursts to go [Q N G M]
time 17821ms: Process O switching out of CPU; will block on I/O until time 19223ms [Q N G M]
time 17825ms: Process N started using the CPU for 189ms burst [Q G M]
time 18014ms: Process N completed a CPU burst; 16 bursts to go [Q G M]
time 18014ms: Process N switching out of CPU; will block on I/O until time 19646ms [Q G M]
time 18018ms: Process G started using the CPU for 7ms burst [Q M]
time 18025ms: Process G completed a CPU burst; 66 bursts to go [Q M]
time 18025ms: Process G switching out of CPU; will block on I/O until time 19667ms [Q M]
time 18029ms: Process M started using the CPU for 15ms burst [Q empty]
time 18044ms: Process M completed a CPU burst; 34 bursts to go [Q empty]
time 18044ms: Process M switching out of CPU; will block on I/O until time 19156ms [Q empty]
time 18064ms: Process E completed I/O; added to ready queue [Q E]
time 18066ms: Process E started using the CPU for 23ms burst [Q empty]
time 18089ms: Process E completed a CPU burst; 40 bursts to go [Q empty]
time 18089ms: Process E switching out of CPU; will block on I/O until time 18181ms [Q empty]
time 18161ms: Process F completed I/O; added to ready queue [Q F]
time 18163ms: Process F started using the CPU for 22ms burst [Q empty]
time 18181ms: Process E completed I/O; added to ready queue [Q E]
time 18185ms: Process F completed a CPU burst; 14 bursts to go [Q E]
time 18185ms: Process F switching out of CPU; will block on I/O until time 18337ms [Q E]
time 18189ms: Process E started using the CPU for 68ms burst [Q empty]
time 18192ms: Process B completed I/O; added to ready queue [Q B]
time 18257ms: Process E completed a CPU burst; 39 bursts to go [Q B]
time 18257ms: Process E switching out of CPU; will block on I/O until time 18839ms [Q B]
time 18261ms: Process B started using the CPU for 33ms burst [Q empty]
time 18294ms: Process B completed a CPU burst; 3 bursts to go [Q empty]
time 18294ms: Process B switching out of CPU; will block on I/O until time 19036ms [Q empty]
time 18337ms: Process F completed I/O; added to ready queue [Q F]
time 18339ms: Process F started using the CPU for 52ms burst [Q empty]
time 18391ms: Process F completed a CPU burst; 13 bursts to go [Q empty]
time 18391ms: Process F switching out of CPU; will block on I/O until time 18483ms [Q empty]
time 18483ms: Process F completed I/O; added to ready queue [Q F]
time 18485ms: Process F started using the CPU for 90ms burst [Q empty]
time 18575ms: Process F completed a CPU burst; 12 bursts to go [Q empty]
time 18575ms: Process F switching out of CPU; will block on I/O until time 20787ms [Q empty]
time 18839ms: Process E completed I/O; added to ready queue [Q E]
time 18841ms: Process E started using the CPU for 41ms burst [Q empty]
time 18853ms: Process H completed I/O; added to ready queue [Q H]
time 18882ms: Process E completed a CPU burst; 38 bursts to go [Q H]
time 18882ms: Process E switching out of CPU; will block on I/O until time 19084ms [Q H]
time 18886ms: Process H started using the CPU for 32ms burst [Q empty]
time 18918ms: Process H completed a CPU burst; 67 bursts to go [Q empty]
time 18918ms: Process H switching out of CPU; will block on I/O until time 19740ms [Q empty]
time 19036ms: Process B completed I/O; added to ready queue [Q B]
time 19038ms: Process B started using the CPU for 63ms burst [Q empty]
time 19064ms: Process I completed I/O; added to ready queue [Q I]
time 19084ms: Process E completed I/O; added to ready queue [Q I E]
time 19101ms: Process B completed a CPU burst; 2 bursts to go [Q I E]
time 19101ms: Process B switching out of CPU; will block on I/O until time 21413ms [Q I E]
time 19105ms: Process I started using the CPU for 95ms burst [Q E]
time 19156ms: Process M completed I/O; added to ready queue [Q E M]
time 19200ms: Process I completed a CPU burst; 62 bursts to go [Q E M]
time 19200ms: Process I switching out of CPU; will block on I/O until time 20622ms [Q E M]
time 19204ms: Process E started using the CPU for 44ms burst [Q M]
time 19223ms: Process O completed I/O; added to ready queue [Q M O]
time 19248ms: Process E completed a CPU burst; 37 bursts to go [Q M O]
time 19248ms: Process E switching out of CPU; will block on I/O until time 19860ms [Q M O]
time 19252ms: Process M started using the CPU for 26ms burst [Q O]
time 19278ms: Process M completed a CPU burst; 33 bursts to go [Q O]
time 19278ms: Process M switching out of CPU; will block on I/O until time 19880ms [Q O]
time 19282ms: Process O started using the CPU for 45ms burst [Q empty]
time 19327ms: Process O completed a CPU burst; 19 bursts to go [Q empty]
time 19327ms: Process O switching out of CPU; will block on I/O until time 19789ms [Q empty]
time 19646ms: Process N completed I/O; added to ready queue [Q N]
time 19648ms: Process N started using the CPU for 67ms burst [Q empty]
time 19667ms: Process G completed I/O; added to ready queue [Q G]
time 19715ms: Process N completed a CPU burst; 15 bursts to go [Q G]
time 19715ms: Process N switching out of CPU; will block on I/O until time 20137ms [Q G]
time 19719ms: Process G started using the CPU for 2ms burst [Q empty]
time 19721ms: Process G completed a CPU burst; 65 bursts to go [Q empty]
time 19721ms: Process G switching out of CPU; will block on I/O until time 19833ms [Q empty]
time 19740ms: Process H completed I/O; added to ready queue [Q H]
time 19742ms: Process H started using the CPU for 78ms burst [Q empty]
time 19789ms: Process O completed I/O; added to ready queue [Q O]
time 19820ms: Process H completed a CPU burst; 66 bursts to go [Q O]
time 19820ms: Process H switching out of CPU; will block on I/O until time 19882ms [Q O]
time 19824ms: Process O started using the CPU for 50ms burst [Q empty]
time 19833ms: Process G completed I/O; added to ready queue [Q G]
time 19860ms: Process E completed I/O; added to ready queue [Q G E]
time 19874ms: Process O completed a CPU burst; 18 bursts to go [Q G E]
time 19874ms: Process O switching out of CPU; will block on I/O until time 20986ms [Q G E]
time 19878ms: Process G started using the CPU for 209ms burst [Q E]
time 19880ms: Process M completed I/O; added to ready queue [Q E M]
time 19882ms: Process H completed I/O; added to ready queue [Q E M H]
time 20087ms: Process G completed a CPU burst; 64 bursts to go [Q E M H]
time 20087ms: Process G switching out of CPU; will block on I/O until time 20569ms [Q E M H]
time 20091ms: Process E started using the CPU for 74ms burst [Q M H]
time 20137ms: Process N completed I/O; added to ready queue [Q M H N]
time 20165ms: Process E completed a CPU burst; 36 bursts to go [Q M H N]
time 20165ms: Process E switching out of CPU; will block on I/O until time 22027ms [Q M H N]
time 20169ms: Process M started using the CPU for 74ms burst [Q H N]
time 20180ms: Process P completed I/O; added to ready queue [Q H N P]
time 20243ms: Process M completed a CPU burst; 32 bursts to go [Q H N P]
time 20243ms: Process M switching out of CPU; will block on I/O until time 21455ms [Q H N P]
time 20247ms: Process H started using the CPU for 16ms burst [Q N P]
time 20263ms: Process H completed a CPU burst; 65 bursts to go [Q N P]
time 20263ms: Process H switching out of CPU; will block on I/O until time 20815ms [Q N P]
time 20267ms: Process N started using the CPU for 35ms burst [Q P]
time 20302ms: Process N completed a CPU burst; 14 bursts to go [Q P]
time 20302ms: Process N switching out of CPU; will block on I/O until time 21344ms [Q P]
time 20306ms: Process P started using the CPU for 212ms burst [Q empty]
time 20518ms: Process P completed a CPU burst; 5 bursts to go [Q empty]
time 20518ms: Process P switching out of CPU; will block on I/O until time 22690ms [Q empty]
time 20569ms: Process G completed I/O; added to ready queue [Q G]
time 20571ms: Process G started using the CPU for 6ms burst [Q empty]
time 20577ms: Process G completed a CPU burst; 63 bursts to go [Q empty]
time 20577ms: Process G switching out of CPU; will block on I/O until time 22059ms [Q empty]
time 20622ms: Process I completed I/O; added to ready queue [Q I]
time 20624ms: Process I started using the CPU for 78ms burst [Q empty]
time 20702ms: Process I completed a CPU burst; 61 bursts to go [Q empty]
time 20702ms: Process I switching out of CPU; will block on I/O until time 21474ms [Q empty]
time 20787ms: Process F completed I/O; added to ready queue [Q F]
time 20789ms: Process F started using the CPU for 4ms burst [Q empty]
time 20793ms: Process F completed a CPU burst; 11 bursts to go [Q empty]
time 20793ms: Process F switching out of CPU; will block on I/O until time 21345ms [Q empty]
time 20815ms: Process H completed I/O; added to ready queue [Q H]
time 20817ms: Process H started using the CPU for 142ms burst [Q empty]
time 20959ms: Process H completed a CPU burst; 64 bursts to go [Q empty]
time 20959ms: Process H switching out of CPU; will block on I/O until time 21931ms [Q empty]
time 20986ms: Process O completed I/O; added to ready queue [Q O]
time 20988ms: Process O started using the CPU for 133ms burst [Q empty]
time 21121ms: Process O completed a CPU burst; 17 bursts to go [Q empty]
time 21121ms: Process O switching out of CPU; will block on I/O until time 22403ms [Q empty]
time 21344ms: Process N completed I/O; added to ready queue [Q N]
time 21346ms: Process N started using the CPU for 2ms burst [Q empty]
time 21345ms: Process F completed I/O; added to ready queue [Q F]
time 21348ms: Process N completed a CPU burst; 13 bursts to go [Q F]
time 21348ms: Process N switching out of CPU; will block on I/O until time 22650ms [Q F]
time 21352ms: Process F started using the CPU for 30ms burst [Q empty]
time 21382ms: Process F completed a CPU burst; 10 bursts to go [Q empty]
time 21382ms: Process F switching out of CPU; will block on I/O until time 21844ms [Q empty]
time 21413ms: Process B completed I/O; added to ready queue [Q B]
time 21415ms: Process B started using the CPU for 170ms burst [Q empty]
time 21455ms: Process M completed I/O; added to ready queue [Q M]
time 21474ms: Process I completed I/O; added to ready queue [Q M I]
time 21585ms: Process B completed a CPU burst; 1 bursts to go [Q M I]
time 21585ms: Process B switching out of CPU; will block on I/O until time 22157ms [Q M I]
time 21589ms: Process M started using the CPU for 6ms burst [Q I]
time 21595ms: Process M completed a CPU burst; 31 bursts to go [Q I]
time 21595ms: Process M switching out of CPU; will block on I/O until time 22637ms [Q I]
time 21599ms: Process I started using the CPU for 31ms burst [Q empty]
time 21630ms: Process I completed a CPU burst; 60 bursts to go [Q empty]
time 21630ms: Process I switching out of CPU; will block on I/O until time 22722ms [Q empty]
time 21844ms: Process F completed I/O; added to ready queue [Q F]
time 21846ms: Process F started using the CPU for 183ms burst [Q empty]
time 21931ms: Process H completed I/O; added to ready queue [Q H]
time 22027ms: Process E completed I/O; added to ready queue [Q H E]
time 22029ms: Process F completed a CPU burst; 9 bursts to go [Q H E]
time 22029ms: Process F switching out of CPU; will block on I/O until time 22441ms [Q H E]
time 22033ms: Process H started using the CPU for 62ms burst [Q E]
time 22059ms: Process G completed I/O; added to ready queue [Q E G]
time 22095ms: Process H completed a CPU burst; 63 bursts to go [Q E G]
time 22095ms: Process H switching out of CPU; will block on I/O until time 22347ms [Q E G]
time 22099ms: Process E started using the CPU for 117ms burst [Q G]
time 22157ms: Process B completed I/O; added to ready queue [Q G B]
time 22216ms: Process E completed a CPU burst; 35 bursts to go [Q G B]
time 22216ms: Process E switching out of CPU; will block on I/O until time 23218ms [Q G B]
time 22220ms: Process G started using the CPU for 37ms burst [Q B]
time 22257ms: Process G completed a CPU burst; 62 bursts to go [Q B]
time 22257ms: Process G switching out of CPU; will block on I/O until time 23569ms [Q B]
time 22261ms: Process B started using the CPU for 212ms burst [Q empty]
time 22347ms: Process H completed I/O; added to ready queue [Q H]
time 22403ms: Process O completed I/O; added to ready queue [Q H O]
time 22441ms: Process F completed I/O; added to ready queue [Q H O F]
time 22473ms: Process B terminated [Q H O F]
time 22477ms: Process H started using the CPU for 248ms burst [Q O F]
time 22637ms: Process M completed I/O; added to ready queue [Q O F M]
time 22650ms: Process N completed I/O; added to ready queue [Q O F M N]
time 22690ms: Process P completed I/O; added to ready queue [Q O F M N P]
time 22722ms: Process I completed I/O; added to ready queue [Q O F M N P I]
time 22725ms: Process H completed a CPU burst; 62 bursts to go [Q O F M N P I]
time 22725ms: Process H switching out of CPU; will block on I/O until time 23547ms [Q O F M N P I]
time 22729ms: Process O started using the CPU for 74ms burst [Q F M N P I]
time 22803ms: Process O completed a CPU burst; 16 bursts to go [Q F M N P I]
time 22803ms: Process O switching out of CPU; will block on I/O until time 23695ms [Q F M N P I]
time 22807ms: Process F started using the CPU for 21ms burst [Q M N P I]
time 22828ms: Process F completed a CPU burst; 8 bursts to go [Q M N P I]
time 22828ms: Process F switching out of CPU; will block on I/O until time 24000ms [Q M N P I]
time 22832ms: Process M started using the CPU for 216ms burst [Q N P I]
time 23048ms: Process M completed a CPU burst; 30 bursts to go [Q N P I]
time 23048ms: Process M switching out of CPU; will block on I/O until time 24250ms [Q N P I]
time 23052ms: Process N started using the CPU for 158ms burst [Q P I]
time 23210ms: Process N completed a CPU burst; 12 bursts to go [Q P I]
time 23210ms: Process N switching out of CPU; will block on I/O until time 25122ms [Q P I]
time 23214ms: Process P started using the CPU for 83ms burst [Q I]
time 23218ms: Process E completed I/O; added to ready queue [Q I E]
time 23297ms: Process P completed a CPU burst; 4 bursts to go [Q I E]
time 23297ms: Process P switching out of CPU; will block on I/O until time 23569ms [Q I E]
time 23301ms: Process I started using the CPU for 97ms burst [Q E]
time 23398ms: Process I completed a CPU burst; 59 bursts to go [Q E]
time 23398ms: Process I switching out of CPU; will block on I/O until time 23580ms [Q E]
time 23402ms: Process E started using the CPU for 14ms burst [Q empty]
time 23416ms: Process E completed a CPU burst; 34 bursts to go [Q empty]
time 23416ms: Process E switching out of CPU; will block on I/O until time 23438ms [Q empty]
time 23438ms: Process E completed I/O; added to ready queue [Q E]
time 23440ms: Process E started using the CPU for 156ms burst [Q empty]
time 23547ms: Process H completed I/O; added to ready queue [Q H]
time 23569ms: Process G completed I/O; added to ready queue [Q H G]
time 23569ms: Process P completed I/O; added to ready queue [Q H G P]
time 23580ms: Process I completed I/O; added to ready queue [Q H G P I]
time 23596ms: Process E completed a CPU burst; 33 bursts to go [Q H G P I]
time 23596ms: Process E switching out of CPU; will block on I/O until time 24598ms [Q H G P I]
time 23600ms: Process H started using the CPU for 37ms burst [Q G P I]
time 23637ms: Process H completed a CPU burst; 61 bursts to go [Q G P I]
time 23637ms: Process H switching out of CPU; will block on I/O until time 23669ms [Q G P I]
time 23641ms: Process G started using the CPU for 15ms burst [Q P I]
time 23656ms: Process G completed a CPU burst; 61 bursts to go [Q P I]
time 23656ms: Process G switching out of CPU; will block on I/O until time 23878ms [Q P I]
time 23660ms: Process P started using the CPU for 75ms burst [Q I]
time 23669ms: Process H completed I/O; added to ready queue [Q I H]
time 23695ms: Process O completed I/O; added to ready queue [Q I H O]
time 23735ms: Process P completed a CPU burst; 3 bursts to go [Q I H O]
time 23735ms: Process P switching out of CPU; will block on I/O until time 23917ms [Q I H O]
time 23739ms: Process I started using the CPU for 103ms burst [Q H O]
time 23842ms: Process I completed a CPU burst; 58 bursts to go [Q H O]
time 23842ms: Process I switching out of CPU; will block on I/O until time 24714ms [Q H O]
time 23846ms: Process H started using the CPU for 10ms burst [Q O]
time 23856ms: Process H completed a CPU burst; 60 bursts to go [Q O]
time 23856ms: Process H switching out of CPU; will block on I/O until time 23918ms [Q O]
time 23860ms: Process O started using the CPU for 41ms burst [Q empty]
time 23878ms: Process G completed I/O; added to ready queue [Q G]
time 23901ms: Process O completed a CPU burst; 15 bursts to go [Q G]
time 23901ms: Process O switching out of CPU; will block on I/O until time 24473ms [Q G]
time 23905ms: Process G started using the CPU for 47ms burst [Q empty]
time 23917ms: Process P completed I/O; added to ready queue [Q P]
time 23918ms: Process H completed I/O; added to ready queue [Q P H]
time 23952ms: Process G completed a CPU burst; 60 bursts to go [Q P H]
time 23952ms: Process G switching out of CPU; will block on I/O until time 24714ms [Q P H]
time 23956ms: Process P started using the CPU for 1ms burst [Q H]
time 23957ms: Process P completed a CPU burst; 2 bursts to go [Q H]
time 23957ms: Process P switching out of CPU; will block on I/O until time 24139ms [Q H]
time 23961ms: Process H started using the CPU for 189ms burst [Q empty]
time 24000ms: Process F completed I/O; added to ready queue [Q F]
time 24139ms: Process P completed I/O; added to ready queue [Q F P]
time 24150ms: Process H completed a CPU burst; 59 bursts to go [Q F P]
time 24150ms: Process H switching out of CPU; will block on I/O until time 24632ms [Q F P]
time 24154ms: Process F started using the CPU for 101ms burst [Q P]
time 24250ms: Process M completed I/O; added to ready queue [Q P M]
time 24255ms: Process F completed a CPU burst; 7 bursts to go [Q P M]
time 24255ms: Process F switching out of CPU; will block on I/O until time 25157ms [Q P M]
time 24259ms: Process P started using the CPU for 131ms burst [Q M]
time 24390ms: Process P completed a CPU burst; 1 bursts to go [Q M]
time 24390ms: Process P switching out of CPU; will block on I/O until time 24842ms [Q M]
time 24394ms: Process M started using the CPU for 3ms burst [Q empty]
time 24397ms: Process M completed a CPU burst; 29 bursts to go [Q empty]
time 24397ms: Process M switching out of CPU; will block on I/O until time 24649ms [Q empty]
time 24473ms: Process O completed I/O; added to ready queue [Q O]
time 24475ms: Process O started using the CPU for 57ms burst [Q empty]
time 24532ms: Process O completed a CPU burst; 14 bursts to go [Q empty]
time 24532ms: Process O switching out of CPU; will block on I/O until time 24814ms [Q empty]
time 24598ms: Process E completed I/O; added to ready queue [Q E]
time 24600ms: Process E started using the CPU for 18ms burst [Q empty]
time 24618ms: Process E completed a CPU burst; 32 bursts to go [Q empty]
time 24618ms: Process E switching out of CPU; will block on I/O until time 25060ms [Q empty]
time 24632ms: Process H completed I/O; added to ready queue [Q H]
time 24634ms: Process H started using the CPU for 134ms burst [Q empty]
time 24649ms: Process M completed I/O; added to ready queue [Q M]
time 24714ms: Process G completed I/O; added to ready queue [Q M G]
time 24714ms: Process I completed I/O; added to ready queue [Q M G I]
time 24768ms: Process H completed a CPU burst; 58 bursts to go [Q M G I]
time 24768ms: Process H switching out of CPU; will block on I/O until time 25100ms [Q M G I]
time 24772ms: Process M started using the CPU for 67ms burst [Q G I]
time 24814ms: Process O completed I/O; added to ready queue [Q G I O]
time 24839ms: Process M completed a CPU burst; 28 bursts to go [Q G I O]
time 24839ms: Process M switching out of CPU; will block on I/O until time 25131ms [Q G I O]
time 24843ms: Process G started using the CPU for 82ms burst [Q I O]
time 24842ms: Process P completed I/O; added to ready queue [Q I O P]
time 24925ms: Process G completed a CPU burst; 59 bursts to go [Q I O P]
time 24925ms: Process G switching out of CPU; will block on I/O until time 24957ms [Q I O P]
time 24929ms: Process I started using the CPU for 44ms burst [Q O P]
time 24957ms: Process G completed I/O; added to ready queue [Q O P G]
time 24973ms: Process I completed a CPU burst; 57 bursts to go [Q O P G]
time 24973ms: Process I switching out of CPU; will block on I/O until time 26965ms [Q O P G]
time 24977ms: Process O started using the CPU for 159ms burst [Q P G]
time 25060ms: Process E completed I/O; added to ready queue [Q P G E]
time 25100ms: Process H completed I/O; added to ready queue [Q P G E H]
time 25122ms: Process N completed I/O; added to ready queue [Q P G E H N]
time 25131ms: Process M completed I/O; added to ready queue [Q P G E H N M]
time 25136ms: Process O completed a CPU burst; 13 bursts to go [Q P G E H N M]
time 25136ms: Process O switching out of CPU; will block on I/O until time 26148ms [Q P G E H N M]
time 25140ms: Process P started using the CPU for 9ms burst [Q G E H N M]
time 25149ms: Process P terminated [Q G E H N M]
time 25153ms: Process G started using the CPU for 57ms burst [Q E H N M]
time 25157ms: Process F completed I/O; added to ready queue [Q E H N M F]
time 25210ms: Process G completed a CPU burst; 58 bursts to go [Q E H N M F]
time 25210ms: Process G switching out of CPU; will block on I/O until time 25422ms [Q E H N M F]
time 25214ms: Process E started using the CPU for 215ms burst [Q H N M F]
time 25422ms: Process G completed I/O; added to ready queue [Q H N M F G]
time 25429ms: Process E completed a CPU burst; 31 bursts to go [Q H N M F G]
time 25429ms: Process E switching out of CPU; will block on I/O until time 25521ms [Q H N M F G]
time 25433ms: Process H started using the CPU for 25ms burst [Q N M F G]
time 25458ms: Process H completed a CPU burst; 57 bursts to go [Q N M F G]
time 25458ms: Process H switching out of CPU; will block on I/O until time 26270ms [Q N M F G]
time 25462ms: Process N started using the CPU for 52ms burst [Q M F G]
time 25514ms: Process N completed a CPU burst; 11 bursts to go [Q M F G]
time 25514ms: Process N switching out of CPU; will block on I/O until time 25536ms [Q M F G]
time 25518ms: Process M started using the CPU for 217ms burst [Q F G]
time 25521ms: Process E completed I/O; added to ready queue [Q F G E]
time 25536ms: Process N completed I/O; added to ready queue [Q F G E N]
time 25735ms: Process M completed a CPU burst; 27 bursts to go [Q F G E N]
time 25735ms: Process M switching out of CPU; will block on I/O until time 26177ms [Q F G E N]
time 25739ms: Process F started using the CPU for 2ms burst [Q G E N]
time 25741ms: Process F completed a CPU burst; 6 bursts to go [Q G E N]
time 25741ms: Process F switching out of CPU; will block on I/O until time 27853ms [Q G E N]
time 25745ms: Process G started using the CPU for 89ms burst [Q E N]
time 25834ms: Process G completed a CPU burst; 57 bursts to go [Q E N]
time 25834ms: Process G switching out of CPU; will block on I/O until time 26756ms [Q E N]
time 25838ms: Process E started using the CPU for 224ms burst [Q N]
time 26062ms: Process E completed a CPU burst; 30 bursts to go [Q N]
time 26062ms: Process E switching out of CPU; will block on I/O until time 27144ms [Q N]
time 26066ms: Process N started using the CPU for 251ms burst [Q empty]
time 26148ms: Process O completed I/O; added to ready queue [Q O]
time 26177ms: Process M completed I/O; added to ready queue [Q O M]
time 26270ms: Process H completed I/O; added to ready queue [Q O M H]
time 26317ms: Process N completed a CPU burst; 10 bursts to go [Q O M H]
time 26317ms: Process N switching out of CPU; will block on I/O until time 28719ms [Q O M H]
time 26321ms: Process O started using the CPU for 87ms burst [Q M H]
time 26408ms: Process O completed a CPU burst; 12 bursts to go [Q M H]
time 26408ms: Process O switching out of CPU; will block on I/O until time 28020ms [Q M H]
time 26412ms: Process M started using the CPU for 19ms burst [Q H]
time 26431ms: Process M completed a CPU burst; 26 bursts to go [Q H]
time 26431ms: Process M switching out of CPU; will block on I/O until time 27833ms [Q H]
time 26435ms: Process H started using the CPU for 235ms burst [Q empty]
time 26670ms: Process H completed a CPU burst; 56 bursts to go [Q empty]
time 26670ms: Process H switching out of CPU; will block on I/O until time 28192ms [Q empty]
time 26756ms: Process G completed I/O; added to ready queue [Q G]
time 26758ms: Process G started using the CPU for 3ms burst [Q empty]
time 26761ms: Process G completed a CPU burst; 56 bursts to go [Q empty]
time 26761ms: Process G switching out of CPU; will block on I/O until time 28123ms [Q empty]
time 26965ms: Process I completed I/O; added to ready queue [Q I]
time 26967ms: Process I started using the CPU for 37ms burst [Q empty]
time 27004ms: Process I completed a CPU burst; 56 bursts to go [Q empty]
time 27004ms: Process I switching out of CPU; will block on I/O until time 27906ms [Q empty]
time 27144ms: Process E completed I/O; added to ready queue [Q E]
time 27146ms: Process E started using the CPU for 1ms burst [Q empty]
time 27147ms: Process E completed a CPU burst; 29 bursts to go [Q empty]
time 27147ms: Process E switching out of CPU; will block on I/O until time 27809ms [Q empty]
time 27809ms: Process E completed I/O; added to ready queue [Q E]
time 27811ms: Process E started using the CPU for 168ms burst [Q empty]
time 27833ms: Process M completed I/O; added to ready queue [Q M]
time 27853ms: Process F completed I/O; added to ready queue [Q M F]
time 27906ms: Process I completed I/O; added to ready queue [Q M F I]
time 27979ms: Process E completed a CPU burst; 28 bursts to go [Q M F I]
time 27979ms: Process E switching out of CPU; will block on I/O until time 29161ms [Q M F I]
time 27983ms: Process M started using the CPU for 73ms burst [Q F I]
time 28020ms: Process O completed I/O; added to ready queue [Q F I O]
time 28056ms: Process M completed a CPU burst; 25 bursts to go [Q F I O]
time 28056ms: Process M switching out of CPU; will block on I/O until time 28928ms [Q F I O]
time 28060ms: Process F started using the CPU for 170ms burst [Q I O]
time 28123ms: Process G completed I/O; added to ready queue [Q I O G]
time 28192ms: Process H completed I/O; added to ready queue [Q I O G H]
time 28230ms: Process F completed a CPU burst; 5 bursts to go [Q I O G H]
time 28230ms: Process F switching out of CPU; will block on I/O until time 28812ms [Q I O G H]
time 28234ms: Process I started using the CPU for 1ms burst [Q O G H]
time 28235ms: Process I completed a CPU burst; 55 bursts to go [Q O G H]
time 28235ms: Process I switching out of CPU; will block on I/O until time 28257ms [Q O G H]
time 28239ms: Process O started using the CPU for 127ms burst [Q G H]
time 28257ms: Process I completed I/O; added to ready queue [Q G H I]
time 28366ms: Process O completed a CPU burst; 11 bursts to go [Q G H I]
time 28366ms: Process O switching out of CPU; will block on I/O until time 30528ms [Q G H I]
time 28370ms: Process G started using the CPU for 11ms burst [Q H I]
time 28381ms: Process G completed a CPU burst; 55 bursts to go [Q H I]
time 28381ms: Process G switching out of CPU; will block on I/O until time 30833ms [Q H I]
time 28385ms: Process H started using the CPU for 105ms burst [Q I]
time 28490ms: Process H completed a CPU burst; 55 bursts to go [Q I]
time 28490ms: Process H switching out of CPU; will block on I/O until time 29232ms [Q I]
time 28494ms: Process I started using the CPU for 96ms burst [Q empty]
time 28590ms: Process I completed a CPU burst; 54 bursts to go [Q empty]
time 28590ms: Process I switching out of CPU; will block on I/O until time 28782ms [Q empty]
time 28719ms: Process N completed I/O; added to ready queue [Q N]
time 28721ms: Process N started using the CPU for 55ms burst [Q empty]
time 28776ms: Process N completed a CPU burst; 9 bursts to go [Q empty]
time 28776ms: Process N switching out of CPU; will block on I/O until time 28928ms [Q empty]
time 28782ms: Process I completed I/O; added to ready queue [Q I]
time 28784ms: Process I started using the CPU for 143ms burst [Q empty]
time 28812ms: Process F completed I/O; added to ready queue [Q F]
time 28927ms: Process I completed a CPU burst; 53 bursts to go [Q F]
time 28927ms: Process I switching out of CPU; will block on I/O until time 29659ms [Q F]
time 28928ms: Process M completed I/O; added to ready queue [Q F M]
time 28928ms: Process N completed I/O; added to ready queue [Q F M N]
time 28931ms: Process F started using the CPU for 154ms burst [Q M N]
time 29085ms: Process F completed a CPU burst; 4 bursts to go [Q M N]
time 29085ms: Process F switching out of CPU; will block on I/O until time 29447ms [Q M N]
time 29089ms: Process M started using the CPU for 36ms burst [Q N]
time 29125ms: Process M completed a CPU burst; 24 bursts to go [Q N]
time 29125ms: Process M switching out of CPU; will block on I/O until time 31007ms [Q N]
time 29129ms: Process N started using the CPU for 32ms burst [Q empty]
time 29161ms: Process E completed I/O; added to ready queue [Q E]
time 29161ms: Process N completed a CPU burst; 8 bursts to go [Q E]
time 29161ms: Process N switching out of CPU; will block on I/O until time 30083ms [Q E]
time 29165ms: Process E started using the CPU for 10ms burst [Q empty]
time 29175ms: Process E completed a CPU burst; 27 bursts to go [Q empty]
time 29175ms: Process E switching out of CPU; will block on I/O until time 29647ms [Q empty]
time 29232ms: Process H completed I/O; added to ready queue [Q H]
time 29234ms: Process H started using the CPU for 75ms burst [Q empty]
time 29309ms: Process H completed a CPU burst; 54 bursts to go [Q empty]
time 29309ms: Process H switching out of CPU; will block on I/O until time 29991ms [Q empty]
time 29447ms: Process F completed I/O; added to ready queue [Q F]
time 29449ms: Process F started using the CPU for 55ms burst [Q empty]
time 29504ms: Process F completed a CPU burst; 3 bursts to go [Q empty]
time 29504ms: Process F switching out of CPU; will block on I/O until time 30756ms [Q empty]
time 29647ms: Process E completed I/O; added to ready queue [Q E]
time 29649ms: Process E started using the CPU for 68ms burst [Q empty]
time 29659ms: Process I completed I/O; added to ready queue [Q I]
time 29717ms: Process E completed a CPU burst; 26 bursts to go [Q I]
time 29717ms: Process E switching out of CPU; will block on I/O until time 30269ms [Q I]
time 29721ms: Process I started using the CPU for 71ms burst [Q empty]
time 29792ms: Process I completed a CPU burst; 52 bursts to go [Q empty]
time 29792ms: Process I switching out of CPU; will block on I/O until time 29824ms [Q empty]
time 29824ms: Process I completed I/O; added to ready queue [Q I]
time 29826ms: Process I started using the CPU for 111ms burst [Q empty]
time 29937ms: Process I completed a CPU burst; 51 bursts to go [Q empty]
time 29937ms: Process I switching out of CPU; will block on I/O until time 30999ms [Q empty]
time 29991ms: Process H completed I/O; added to ready queue [Q H]
time 29993ms: Process H started using the CPU for 141ms burst [Q empty]
time 30083ms: Process N completed I/O; added to ready queue [Q N]
time 30134ms: Process H completed a CPU burst; 53 bursts to go [Q N]
time 30134ms: Process H switching out of CPU; will block on I/O until time 30216ms [Q N]
time 30138ms: Process N started using the CPU for 101ms burst [Q empty]
time 30216ms: Process H completed I/O; added to ready queue [Q H]
time 30239ms: Process N completed a CPU burst; 7 bursts to go [Q H]
time 30239ms: Process N switching out of CPU; will block on I/O until time 31991ms [Q H]
time 30243ms: Process H started using the CPU for 63ms burst [Q empty]
time 30269ms: Process E completed I/O; added to ready queue [Q E]
time 30306ms: Process H completed a CPU burst; 52 bursts to go [Q E]
time 30306ms: Process H switching out of CPU; will block on I/O until time 31018ms [Q E]
time 30310ms: Process E started using the CPU for 30ms burst [Q empty]
time 30340ms: Process E completed a CPU burst; 25 bursts to go [Q empty]
time 30340ms: Process E switching out of CPU; will block on I/O until time 31312ms [Q empty]
time 30528ms: Process O completed I/O; added to ready queue [Q O]
time 30530ms: Process O started using the CPU for 9ms burst [Q empty]
time 30539ms: Process O completed a CPU burst; 10 bursts to go [Q empty]
time 30539ms: Process O switching out of CPU; will block on I/O until time 30611ms [Q empty]
time 30611ms: Process O completed I/O; added to ready queue [Q O]
time 30613ms: Process O started using the CPU for 54ms burst [Q empty]
time 30667ms: Process O completed a CPU burst; 9 bursts to go [Q empty]
time 30667ms: Process O switching out of CPU; will block on I/O until time 30899ms [Q empty]
time 30756ms: Process F completed I/O; added to ready queue [Q F]
time 30758ms: Process F started using the CPU for 234ms burst [Q empty]
time 30833ms: Process G completed I/O; added to ready queue [Q G]
time 30899ms: Process O completed I/O; added to ready queue [Q G O]
time 30992ms: Process F completed a CPU burst; 2 bursts to go [Q G O]
time 30992ms: Process F switching out of CPU; will block on I/O until time 31264ms [Q G O]
time 30996ms: Process G started using the CPU for 17ms burst [Q O]
time 30999ms: Process I completed I/O; added to ready queue [Q O I]
time 31007ms: Process M completed I/O; added to ready queue [Q O I M]
time 31013ms: Process G completed a CPU burst; 54 bursts to go [Q O I M]
time 31013ms: Process G switching out of CPU; will block on I/O until time 31665ms [Q O I M]
time 31017ms: Process O started using the CPU for 41ms burst [Q I M]
time 31018ms: Process H completed I/O; added to ready queue [Q I M H]
time 31058ms: Process O completed a CPU burst; 8 bursts to go [Q I M H]
time 31058ms: Process O switching out of CPU; will block on I/O until time 31330ms [Q I M H]
time 31062ms: Process I started using the CPU for 81ms burst [Q M H]
time 31143ms: Process I completed a CPU burst; 50 bursts to go [Q M H]
time 31143ms: Process I switching out of CPU; will block on I/O until time 32125ms [Q M H]
time 31147ms: Process M started using the CPU for 212ms burst [Q H]
time 31264ms: Process F completed I/O; added to ready queue [Q H F]
time 31312ms: Process E completed I/O; added to ready queue [Q H F E]
time 31330ms: Process O completed I/O; added to ready queue [Q H F E O]
time 31359ms: Process M completed a CPU burst; 23 bursts to go [Q H F E O]
time 31359ms: Process M switching out of CPU; will block on I/O until time 31721ms [Q H F E O]
time 31363ms: Process H started using the CPU for 93ms burst [Q F E O]
time 31456ms: Process H completed a CPU burst; 51 bursts to go [Q F E O]
time 31456ms: Process H switching out of CPU; will block on I/O until time 32098ms [Q F E O]
time 31460ms: Process F started using the CPU for 122ms burst [Q E O]
