Process A (arrival time 9 ms) 16 CPU bursts (tau 100ms)


time 0ms: Simulator started for FCFS [Q empty]
time 9ms: Process A arrived; added to ready queue [Q A]
time 11ms: Process A started using the CPU for 56ms burst [Q empty]
time 67ms: Process A completed a CPU burst; 15 bursts to go [Q empty]
time 67ms: Process A switching out of CPU; will block on I/O until time 299ms [Q empty]
time 299ms: Process A completed I/O; added to ready queue [Q A]
time 301ms: Process A started using the CPU for 60ms burst [Q empty]
time 361ms: Process A completed a CPU burst; 14 bursts to go [Q empty]
time 361ms: Process A switching out of CPU; will block on I/O until time 1893ms [Q empty]
time 1893ms: Process A completed I/O; added to ready queue [Q A]
time 1895ms: Process A started using the CPU for 39ms burst [Q empty]
time 1934ms: Process A completed a CPU burst; 13 bursts to go [Q empty]
time 1934ms: Process A switching out of CPU; will block on I/O until time 2436ms [Q empty]
time 2436ms: Process A completed I/O; added to ready queue [Q A]
time 2438ms: Process A started using the CPU for 47ms burst [Q empty]
time 2485ms: Process A completed a CPU burst; 12 bursts to go [Q empty]
time 2485ms: Process A switching out of CPU; will block on I/O until time 2507ms [Q empty]
time 2507ms: Process A completed I/O; added to ready queue [Q A]
time 2509ms: Process A started using the CPU for 137ms burst [Q empty]
time 2646ms: Process A completed a CPU burst; 11 bursts to go [Q empty]
time 2646ms: Process A switching out of CPU; will block on I/O until time 2888ms [Q empty]
time 2888ms: Process A completed I/O; added to ready queue [Q A]
time 2890ms: Process A started using the CPU for 64ms burst [Q empty]
time 2954ms: Process A completed a CPU burst; 10 bursts to go [Q empty]
time 2954ms: Process A switching out of CPU; will block on I/O until time 3106ms [Q empty]
time 3106ms: Process A completed I/O; added to ready queue [Q A]
time 3108ms: Process A started using the CPU for 68ms burst [Q empty]
time 3176ms: Process A completed a CPU burst; 9 bursts to go [Q empty]
time 3176ms: Process A switching out of CPU; will block on I/O until time 3818ms [Q empty]
time 3818ms: Process A completed I/O; added to ready queue [Q A]
time 3820ms: Process A started using the CPU for 113ms burst [Q empty]
time 3933ms: Process A completed a CPU burst; 8 bursts to go [Q empty]
time 3933ms: Process A switching out of CPU; will block on I/O until time 4095ms [Q empty]
time 4095ms: Process A completed I/O; added to ready queue [Q A]
time 4097ms: Process A started using the CPU for 11ms burst [Q empty]
time 4108ms: Process A completed a CPU burst; 7 bursts to go [Q empty]
time 4108ms: Process A switching out of CPU; will block on I/O until time 5730ms [Q empty]
time 5730ms: Process A completed I/O; added to ready queue [Q A]
time 5732ms: Process A started using the CPU for 24ms burst [Q empty]
time 5756ms: Process A completed a CPU burst; 6 bursts to go [Q empty]
time 5756ms: Process A switching out of CPU; will block on I/O until time 6928ms [Q empty]
time 6928ms: Process A completed I/O; added to ready queue [Q A]
time 6930ms: Process A started using the CPU for 76ms burst [Q empty]
time 7006ms: Process A completed a CPU burst; 5 bursts to go [Q empty]
time 7006ms: Process A switching out of CPU; will block on I/O until time 7288ms [Q empty]
time 7288ms: Process A completed I/O; added to ready queue [Q A]
time 7290ms: Process A started using the CPU for 122ms burst [Q empty]
time 7412ms: Process A completed a CPU burst; 4 bursts to go [Q empty]
time 7412ms: Process A switching out of CPU; will block on I/O until time 7744ms [Q empty]
time 7744ms: Process A completed I/O; added to ready queue [Q A]
time 7746ms: Process A started using the CPU for 9ms burst [Q empty]
time 7755ms: Process A completed a CPU burst; 3 bursts to go [Q empty]
time 7755ms: Process A switching out of CPU; will block on I/O until time 8437ms [Q empty]
time 8437ms: Process A completed I/O; added to ready queue [Q A]
time 8439ms: Process A started using the CPU for 62ms burst [Q empty]
time 8501ms: Process A completed a CPU burst; 2 bursts to go [Q empty]
time 8501ms: Process A switching out of CPU; will block on I/O until time 9273ms [Q empty]
time 9273ms: Process A completed I/O; added to ready queue [Q A]
time 9275ms: Process A started using the CPU for 200ms burst [Q empty]
time 9475ms: Process A completed a CPU burst; 1 bursts to go [Q empty]
time 9475ms: Process A switching out of CPU; will block on I/O until time 9587ms [Q empty]
time 9587ms: Process A completed I/O; added to ready queue [Q A]
time 9589ms: Process A started using the CPU for 197ms burst [Q empty]
time 9786ms: Process A terminated [Q empty]
Algorithm FCFS
-- average CPU burst time: 80.312 ms
-- average wait time: 0.000 ms
-- average turnaround time: 84.312 ms
-- total number of context switches: 16
-- total number of preemptions: 0
-- CPU utilization: 13.128%
time 0ms: Simulator started for SRT [Q empty]
time 9ms: Process A arrived; added to ready queue [Q A]
time 11ms: Process A (tau 100ms) started using the CPU for 56ms burst [Q empty]
time 67ms: Process A (tau 100ms) completed a CPU burst; 15 bursts to go [Q empty]
time 67ms: Process A switching out of CPU; will block on I/O until time 299ms [Q empty]
time 68ms: Process A (tau 100ms) completed I/O; added to ready queue [Q A]
time 70ms: Process A (tau 100ms) started using the CPU for 60ms burst [Q empty]
time 130ms: Process A (tau 100ms) completed a CPU burst; 14 bursts to go [Q empty]
time 130ms: Process A switching out of CPU; will block on I/O until time 1662ms [Q empty]
time 131ms: Process A (tau 100ms) completed I/O; added to ready queue [Q A]
time 133ms: Process A (tau 100ms) started using the CPU for 39ms burst [Q empty]
time 172ms: Process A (tau 100ms) completed a CPU burst; 13 bursts to go [Q empty]
time 172ms: Process A switching out of CPU; will block on I/O until time 674ms [Q empty]
time 173ms: Process A (tau 100ms) completed I/O; added to ready queue [Q A]
time 175ms: Process A (tau 100ms) started using the CPU for 47ms burst [Q empty]
time 222ms: Process A (tau 100ms) completed a CPU burst; 12 bursts to go [Q empty]
time 222ms: Process A switching out of CPU; will block on I/O until time 244ms [Q empty]
time 223ms: Process A (tau 100ms) completed I/O; added to ready queue [Q A]
time 225ms: Process A (tau 100ms) started using the CPU for 137ms burst [Q empty]
time 362ms: Process A (tau 100ms) completed a CPU burst; 11 bursts to go [Q empty]
time 362ms: Process A switching out of CPU; will block on I/O until time 604ms [Q empty]
time 363ms: Process A (tau 100ms) completed I/O; added to ready queue [Q A]
time 365ms: Process A (tau 100ms) started using the CPU for 64ms burst [Q empty]
time 429ms: Process A (tau 100ms) completed a CPU burst; 10 bursts to go [Q empty]
time 429ms: Process A switching out of CPU; will block on I/O until time 581ms [Q empty]
time 430ms: Process A (tau 100ms) completed I/O; added to ready queue [Q A]
time 432ms: Process A (tau 100ms) started using the CPU for 68ms burst [Q empty]
time 500ms: Process A (tau 100ms) completed a CPU burst; 9 bursts to go [Q empty]
time 500ms: Process A switching out of CPU; will block on I/O until time 1142ms [Q empty]
time 501ms: Process A (tau 100ms) completed I/O; added to ready queue [Q A]
time 503ms: Process A (tau 100ms) started using the CPU for 113ms burst [Q empty]
time 616ms: Process A (tau 100ms) completed a CPU burst; 8 bursts to go [Q empty]
time 616ms: Process A switching out of CPU; will block on I/O until time 778ms [Q empty]
time 617ms: Process A (tau 100ms) completed I/O; added to ready queue [Q A]
time 619ms: Process A (tau 100ms) started using the CPU for 11ms burst [Q empty]
time 630ms: Process A (tau 100ms) completed a CPU burst; 7 bursts to go [Q empty]
time 630ms: Process A switching out of CPU; will block on I/O until time 2252ms [Q empty]
time 631ms: Process A (tau 100ms) completed I/O; added to ready queue [Q A]
time 633ms: Process A (tau 100ms) started using the CPU for 24ms burst [Q empty]
time 657ms: Process A (tau 100ms) completed a CPU burst; 6 bursts to go [Q empty]
time 657ms: Process A switching out of CPU; will block on I/O until time 1829ms [Q empty]
time 658ms: Process A (tau 100ms) completed I/O; added to ready queue [Q A]
time 660ms: Process A (tau 100ms) started using the CPU for 76ms burst [Q empty]
time 736ms: Process A (tau 100ms) completed a CPU burst; 5 bursts to go [Q empty]
time 736ms: Process A switching out of CPU; will block on I/O until time 1018ms [Q empty]
time 737ms: Process A (tau 100ms) completed I/O; added to ready queue [Q A]
time 739ms: Process A (tau 100ms) started using the CPU for 122ms burst [Q empty]
time 861ms: Process A (tau 100ms) completed a CPU burst; 4 bursts to go [Q empty]
time 861ms: Process A switching out of CPU; will block on I/O until time 1193ms [Q empty]
time 862ms: Process A (tau 100ms) completed I/O; added to ready queue [Q A]
time 864ms: Process A (tau 100ms) started using the CPU for 9ms burst [Q empty]
time 873ms: Process A (tau 100ms) completed a CPU burst; 3 bursts to go [Q empty]
time 873ms: Process A switching out of CPU; will block on I/O until time 1555ms [Q empty]
time 874ms: Process A (tau 100ms) completed I/O; added to ready queue [Q A]
time 876ms: Process A (tau 100ms) started using the CPU for 62ms burst [Q empty]
time 938ms: Process A (tau 100ms) completed a CPU burst; 2 bursts to go [Q empty]
time 938ms: Process A switching out of CPU; will block on I/O until time 1710ms [Q empty]
time 939ms: Process A (tau 100ms) completed I/O; added to ready queue [Q A]
time 941ms: Process A (tau 100ms) started using the CPU for 200ms burst [Q empty]
time 1141ms: Process A (tau 100ms) completed a CPU burst; 1 bursts to go [Q empty]
time 1141ms: Process A switching out of CPU; will block on I/O until time 1253ms [Q empty]
time 1142ms: Process A (tau 100ms) completed I/O; added to ready queue [Q A]
time 1144ms: Process A (tau 100ms) started using the CPU for 197ms burst [Q empty]
time 1341ms: Process A terminated [Q empty]
Algorithm SRT
-- average CPU burst time: 80.312 ms
-- average wait time: 0.000 ms
-- average turnaround time: 84.312 ms
-- total number of context switches: 16
-- total number of preemptions: 0
-- CPU utilization: 95.681%
