time 0ms: Simulator started for FCFS [Q empty]
time 9ms: Process A arrived; added to ready queue [Q A]
time 11ms: Process A started using the CPU for 56ms burst [Q empty]
time 67ms: Process A completed a CPU burst; 15 bursts to go [Q empty]
time 67ms: Process A switching out of CPU; will block on I/O until time 299ms [Q empty]
time 299ms: Process A completed I/O; added to ready queue [Q A]
time 301ms: Process A started using the CPU for 60ms burst [Q empty]
time 361ms: Process A completed a CPU burst; 14 bursts to go [Q empty]
time 361ms: Process A switching out of CPU; will block on I/O until time 1893ms [Q empty]
time 1893ms: Process A completed I/O; added to ready queue [Q A]
time 1895ms: Process A started using the CPU for 39ms burst [Q empty]
time 1934ms: Process A completed a CPU burst; 13 bursts to go [Q empty]
time 1934ms: Process A switching out of CPU; will block on I/O until time 2436ms [Q empty]
time 2436ms: Process A completed I/O; added to ready queue [Q A]
time 2438ms: Process A started using the CPU for 47ms burst [Q empty]
time 2485ms: Process A completed a CPU burst; 12 bursts to go [Q empty]
time 2485ms: Process A switching out of CPU; will block on I/O until time 2507ms [Q empty]
time 2507ms: Process A completed I/O; added to ready queue [Q A]
time 2509ms: Process A started using the CPU for 137ms burst [Q empty]
time 2646ms: Process A completed a CPU burst; 11 bursts to go [Q empty]
time 2646ms: Process A switching out of CPU; will block on I/O until time 2888ms [Q empty]
time 2888ms: Process A completed I/O; added to ready queue [Q A]
time 2890ms: Process A started using the CPU for 64ms burst [Q empty]
time 2954ms: Process A completed a CPU burst; 10 bursts to go [Q empty]
time 2954ms: Process A switching out of CPU; will block on I/O until time 3106ms [Q empty]
time 3106ms: Process A completed I/O; added to ready queue [Q A]
time 3108ms: Process A started using the CPU for 68ms burst [Q empty]
time 3176ms: Process A completed a CPU burst; 9 bursts to go [Q empty]
time 3176ms: Process A switching out of CPU; will block on I/O until time 3818ms [Q empty]
time 3818ms: Process A completed I/O; added to ready queue [Q A]
time 3820ms: Process A started using the CPU for 113ms burst [Q empty]
time 3933ms: Process A completed a CPU burst; 8 bursts to go [Q empty]
time 3933ms: Process A switching out of CPU; will block on I/O until time 4095ms [Q empty]
time 4095ms: Process A completed I/O; added to ready queue [Q A]
time 4097ms: Process A started using the CPU for 11ms burst [Q empty]
time 4108ms: Process A completed a CPU burst; 7 bursts to go [Q empty]
time 4108ms: Process A switching out of CPU; will block on I/O until time 5730ms [Q empty]
time 5730ms: Process A completed I/O; added to ready queue [Q A]
time 5732ms: Process A started using the CPU for 24ms burst [Q empty]
time 5756ms: Process A completed a CPU burst; 6 bursts to go [Q empty]
time 5756ms: Process A switching out of CPU; will block on I/O until time 6928ms [Q empty]
time 6928ms: Process A completed I/O; added to ready queue [Q A]
time 6930ms: Process A started using the CPU for 76ms burst [Q empty]
time 7006ms: Process A completed a CPU burst; 5 bursts to go [Q empty]
time 7006ms: Process A switching out of CPU; will block on I/O until time 7288ms [Q empty]
time 7288ms: Process A completed I/O; added to ready queue [Q A]
time 7290ms: Process A started using the CPU for 122ms burst [Q empty]
time 7412ms: Process A completed a CPU burst; 4 bursts to go [Q empty]
time 7412ms: Process A switching out of CPU; will block on I/O until time 7744ms [Q empty]
time 7744ms: Process A completed I/O; added to ready queue [Q A]
time 7746ms: Process A started using the CPU for 9ms burst [Q empty]
time 7755ms: Process A completed a CPU burst; 3 bursts to go [Q empty]
time 7755ms: Process A switching out of CPU; will block on I/O until time 8437ms [Q empty]
time 8437ms: Process A completed I/O; added to ready queue [Q A]
time 8439ms: Process A started using the CPU for 62ms burst [Q empty]
time 8501ms: Process A completed a CPU burst; 2 bursts to go [Q empty]
time 8501ms: Process A switching out of CPU; will block on I/O until time 9273ms [Q empty]
time 9273ms: Process A completed I/O; added to ready queue [Q A]
time 9275ms: Process A started using the CPU for 200ms burst [Q empty]
time 9475ms: Process A completed a CPU burst; 1 bursts to go [Q empty]
time 9475ms: Process A switching out of CPU; will block on I/O until time 9587ms [Q empty]
time 9587ms: Process A completed I/O; added to ready queue [Q A]
time 9589ms: Process A started using the CPU for 197ms burst [Q empty]
time 9786ms: Process A terminated [Q empty]
Algorithm FCFS
-- average CPU burst time: 80.312 ms
-- average wait time: 0.000 ms
-- average turnaround time: 84.312 ms
-- total number of context switches: 16
-- total number of preemptions: 0
-- CPU utilization: 13.128%
time 0ms: Simulator started for SRT [Q empty]
time 0ms: Process A arrived; added to ready queue [Q A]
time 2ms: Process A started using the CPU for 56ms burst [Q empty]
time 58ms: Process A completed a CPU burst; 15 bursts to go [Q empty]
time 58ms: Process A switching out of CPU; will block on I/O until time 290ms [Q empty]
time 291ms: Process A completed I/O; added to ready queue [Q A]
time 293ms: Process A started using the CPU for 60ms burst [Q empty]
time 353ms: Process A completed a CPU burst; 14 bursts to go [Q empty]
time 353ms: Process A switching out of CPU; will block on I/O until time 1885ms [Q empty]
time 1886ms: Process A completed I/O; added to ready queue [Q A]
time 1888ms: Process A started using the CPU for 39ms burst [Q empty]
time 1927ms: Process A completed a CPU burst; 13 bursts to go [Q empty]
time 1927ms: Process A switching out of CPU; will block on I/O until time 2429ms [Q empty]
time 2430ms: Process A completed I/O; added to ready queue [Q A]
time 2432ms: Process A started using the CPU for 47ms burst [Q empty]
time 2479ms: Process A completed a CPU burst; 12 bursts to go [Q empty]
time 2479ms: Process A switching out of CPU; will block on I/O until time 2501ms [Q empty]
time 2502ms: Process A completed I/O; added to ready queue [Q A]
time 2504ms: Process A started using the CPU for 137ms burst [Q empty]
time 2641ms: Process A completed a CPU burst; 11 bursts to go [Q empty]
time 2641ms: Process A switching out of CPU; will block on I/O until time 2883ms [Q empty]
time 2884ms: Process A completed I/O; added to ready queue [Q A]
time 2886ms: Process A started using the CPU for 64ms burst [Q empty]
time 2950ms: Process A completed a CPU burst; 10 bursts to go [Q empty]
time 2950ms: Process A switching out of CPU; will block on I/O until time 3102ms [Q empty]
time 3103ms: Process A completed I/O; added to ready queue [Q A]
time 3105ms: Process A started using the CPU for 68ms burst [Q empty]
time 3173ms: Process A completed a CPU burst; 9 bursts to go [Q empty]
time 3173ms: Process A switching out of CPU; will block on I/O until time 3815ms [Q empty]
time 3816ms: Process A completed I/O; added to ready queue [Q A]
time 3818ms: Process A started using the CPU for 113ms burst [Q empty]
time 3931ms: Process A completed a CPU burst; 8 bursts to go [Q empty]
time 3931ms: Process A switching out of CPU; will block on I/O until time 4093ms [Q empty]
time 4094ms: Process A completed I/O; added to ready queue [Q A]
time 4096ms: Process A started using the CPU for 11ms burst [Q empty]
time 4107ms: Process A completed a CPU burst; 7 bursts to go [Q empty]
time 4107ms: Process A switching out of CPU; will block on I/O until time 5729ms [Q empty]
time 5730ms: Process A completed I/O; added to ready queue [Q A]
time 5732ms: Process A started using the CPU for 24ms burst [Q empty]
time 5756ms: Process A completed a CPU burst; 6 bursts to go [Q empty]
time 5756ms: Process A switching out of CPU; will block on I/O until time 6928ms [Q empty]
time 6929ms: Process A completed I/O; added to ready queue [Q A]
time 6931ms: Process A started using the CPU for 76ms burst [Q empty]
time 7007ms: Process A completed a CPU burst; 5 bursts to go [Q empty]
time 7007ms: Process A switching out of CPU; will block on I/O until time 7289ms [Q empty]
time 7290ms: Process A completed I/O; added to ready queue [Q A]
time 7292ms: Process A started using the CPU for 122ms burst [Q empty]
time 7414ms: Process A completed a CPU burst; 4 bursts to go [Q empty]
time 7414ms: Process A switching out of CPU; will block on I/O until time 7746ms [Q empty]
time 7747ms: Process A completed I/O; added to ready queue [Q A]
time 7749ms: Process A started using the CPU for 9ms burst [Q empty]
time 7758ms: Process A completed a CPU burst; 3 bursts to go [Q empty]
time 7758ms: Process A switching out of CPU; will block on I/O until time 8440ms [Q empty]
time 8441ms: Process A completed I/O; added to ready queue [Q A]
time 8443ms: Process A started using the CPU for 62ms burst [Q empty]
time 8505ms: Process A completed a CPU burst; 2 bursts to go [Q empty]
time 8505ms: Process A switching out of CPU; will block on I/O until time 9277ms [Q empty]
time 9278ms: Process A completed I/O; added to ready queue [Q A]
time 9280ms: Process A started using the CPU for 200ms burst [Q empty]
time 9480ms: Process A completed a CPU burst; 1 bursts to go [Q empty]
time 9480ms: Process A switching out of CPU; will block on I/O until time 9592ms [Q empty]
time 9593ms: Process A completed I/O; added to ready queue [Q A]
time 9595ms: Process A started using the CPU for 197ms burst [Q empty]
time 9792ms: Process A terminated [Q empty]
Algorithm SRT
-- average CPU burst time: 80.312 ms
-- average wait time: 0.000 ms
-- average turnaround time: 84.312 ms
-- total number of context switches: 16
-- total number of preemptions: 0
-- CPU utilization: 13.120%
